/home/hkngae/anaconda3/envs/myenv/lib/python3.10/site-packages/vllm/connections.py:8: RuntimeWarning: Failed to read commit hash:
No module named 'vllm._version'
  from vllm.version import __version__ as VLLM_VERSION
Traceback (most recent call last):
  File "/home/hkngae/anaconda3/envs/myenv/bin/vllm", line 8, in <module>
    sys.exit(main())
  File "/home/hkngae/anaconda3/envs/myenv/lib/python3.10/site-packages/vllm/scripts.py", line 195, in main
    args.dispatch_function(args)
  File "/home/hkngae/anaconda3/envs/myenv/lib/python3.10/site-packages/vllm/scripts.py", line 41, in serve
    uvloop.run(run_server(args))
  File "/home/hkngae/anaconda3/envs/myenv/lib/python3.10/site-packages/uvloop/__init__.py", line 82, in run
    return loop.run_until_complete(wrapper())
  File "uvloop/loop.pyx", line 1517, in uvloop.loop.Loop.run_until_complete
  File "/home/hkngae/anaconda3/envs/myenv/lib/python3.10/site-packages/uvloop/__init__.py", line 61, in wrapper
    return await main
  File "/home/hkngae/anaconda3/envs/myenv/lib/python3.10/site-packages/vllm/entrypoints/openai/api_server.py", line 544, in run_server
    sock.bind(("", args.port))
OSError: [Errno 98] Address already in use
/home/hkngae/anaconda3/envs/myenv/lib/python3.10/site-packages/vllm/connections.py:8: RuntimeWarning: Failed to read commit hash:
No module named 'vllm._version'
  from vllm.version import __version__ as VLLM_VERSION
/home/hkngae/anaconda3/envs/myenv/lib/python3.10/site-packages/vllm/connections.py:8: RuntimeWarning: Failed to read commit hash:
No module named 'vllm._version'
  from vllm.version import __version__ as VLLM_VERSION
/home/hkngae/anaconda3/envs/myenv/lib/python3.10/site-packages/vllm/connections.py:8: RuntimeWarning: Failed to read commit hash:
No module named 'vllm._version'
  from vllm.version import __version__ as VLLM_VERSION
/home/hkngae/anaconda3/envs/myenv/lib/python3.10/site-packages/vllm/connections.py:8: RuntimeWarning: Failed to read commit hash:
No module named 'vllm._version'
  from vllm.version import __version__ as VLLM_VERSION
/home/hkngae/anaconda3/envs/myenv/lib/python3.10/site-packages/vllm/connections.py:8: RuntimeWarning: Failed to read commit hash:
No module named 'vllm._version'
  from vllm.version import __version__ as VLLM_VERSION
Loading safetensors checkpoint shards:   0% Completed | 0/4 [00:00<?, ?it/s]
Loading safetensors checkpoint shards:  25% Completed | 1/4 [00:00<00:01,  1.98it/s]
Loading safetensors checkpoint shards:  50% Completed | 2/4 [00:01<00:01,  2.00it/s]
Loading safetensors checkpoint shards:  75% Completed | 3/4 [00:01<00:00,  3.00it/s]
Loading safetensors checkpoint shards: 100% Completed | 4/4 [00:01<00:00,  2.71it/s]
Loading safetensors checkpoint shards: 100% Completed | 4/4 [00:01<00:00,  2.56it/s]

INFO:     Started server process [1239450]
INFO:     Waiting for application startup.
INFO:     Application startup complete.
INFO:     Uvicorn running on socket ('0.0.0.0', 8000) (Press CTRL+C to quit)
Process SpawnProcess-1:
Traceback (most recent call last):
  File "/home/hkngae/anaconda3/envs/myenv/lib/python3.10/multiprocessing/process.py", line 314, in _bootstrap
    self.run()
  File "/home/hkngae/anaconda3/envs/myenv/lib/python3.10/multiprocessing/process.py", line 108, in run
    self._target(*self._args, **self._kwargs)
  File "/home/hkngae/anaconda3/envs/myenv/lib/python3.10/site-packages/vllm/engine/multiprocessing/engine.py", line 395, in run_mp_engine
    engine.start()
  File "/home/hkngae/anaconda3/envs/myenv/lib/python3.10/site-packages/vllm/engine/multiprocessing/engine.py", line 165, in start
    self.cleanup()
  File "/home/hkngae/anaconda3/envs/myenv/lib/python3.10/site-packages/vllm/engine/multiprocessing/engine.py", line 388, in signal_handler
    raise KeyboardInterrupt("MQLLMEngine terminated")
KeyboardInterrupt: MQLLMEngine terminated
INFO:     Shutting down
INFO:     Waiting for application shutdown.
INFO:     Application shutdown complete.
/home/hkngae/anaconda3/envs/myenv/lib/python3.10/multiprocessing/resource_tracker.py:224: UserWarning: resource_tracker: There appear to be 3 leaked semaphore objects to clean up at shutdown
  warnings.warn('resource_tracker: There appear to be %d '
/home/hkngae/anaconda3/envs/myenv/lib/python3.10/multiprocessing/resource_tracker.py:224: UserWarning: resource_tracker: There appear to be 1 leaked shared_memory objects to clean up at shutdown
  warnings.warn('resource_tracker: There appear to be %d '
/home/hkngae/anaconda3/envs/myenv/lib/python3.10/site-packages/vllm/connections.py:8: RuntimeWarning: Failed to read commit hash:
No module named 'vllm._version'
  from vllm.version import __version__ as VLLM_VERSION
/home/hkngae/anaconda3/envs/myenv/lib/python3.10/site-packages/vllm/connections.py:8: RuntimeWarning: Failed to read commit hash:
No module named 'vllm._version'
  from vllm.version import __version__ as VLLM_VERSION
/home/hkngae/anaconda3/envs/myenv/lib/python3.10/site-packages/vllm/connections.py:8: RuntimeWarning: Failed to read commit hash:
No module named 'vllm._version'
  from vllm.version import __version__ as VLLM_VERSION
/home/hkngae/anaconda3/envs/myenv/lib/python3.10/site-packages/vllm/connections.py:8: RuntimeWarning: Failed to read commit hash:
No module named 'vllm._version'
  from vllm.version import __version__ as VLLM_VERSION
/home/hkngae/anaconda3/envs/myenv/lib/python3.10/site-packages/vllm/connections.py:8: RuntimeWarning: Failed to read commit hash:
No module named 'vllm._version'
  from vllm.version import __version__ as VLLM_VERSION
Loading safetensors checkpoint shards:   0% Completed | 0/4 [00:00<?, ?it/s]
Loading safetensors checkpoint shards:  25% Completed | 1/4 [00:00<00:01,  2.04it/s]
Loading safetensors checkpoint shards:  50% Completed | 2/4 [00:00<00:00,  2.02it/s]
Loading safetensors checkpoint shards:  75% Completed | 3/4 [00:01<00:00,  3.05it/s]
Loading safetensors checkpoint shards: 100% Completed | 4/4 [00:01<00:00,  2.76it/s]
Loading safetensors checkpoint shards: 100% Completed | 4/4 [00:01<00:00,  2.61it/s]

INFO:     Started server process [1241449]
INFO:     Waiting for application startup.
INFO:     Application startup complete.
INFO:     Uvicorn running on socket ('0.0.0.0', 8000) (Press CTRL+C to quit)
Process SpawnProcess-1:
Traceback (most recent call last):
  File "/home/hkngae/anaconda3/envs/myenv/lib/python3.10/multiprocessing/process.py", line 314, in _bootstrap
    self.run()
  File "/home/hkngae/anaconda3/envs/myenv/lib/python3.10/multiprocessing/process.py", line 108, in run
    self._target(*self._args, **self._kwargs)
  File "/home/hkngae/anaconda3/envs/myenv/lib/python3.10/site-packages/vllm/engine/multiprocessing/engine.py", line 395, in run_mp_engine
    engine.start()
  File "/home/hkngae/anaconda3/envs/myenv/lib/python3.10/site-packages/vllm/engine/multiprocessing/engine.py", line 165, in start
    self.cleanup()
  File "/home/hkngae/anaconda3/envs/myenv/lib/python3.10/site-packages/vllm/engine/multiprocessing/engine.py", line 388, in signal_handler
    raise KeyboardInterrupt("MQLLMEngine terminated")
KeyboardInterrupt: MQLLMEngine terminated
INFO:     Shutting down
INFO:     Waiting for application shutdown.
INFO:     Application shutdown complete.
/home/hkngae/anaconda3/envs/myenv/lib/python3.10/multiprocessing/resource_tracker.py:224: UserWarning: resource_tracker: There appear to be 3 leaked semaphore objects to clean up at shutdown
  warnings.warn('resource_tracker: There appear to be %d '
/home/hkngae/anaconda3/envs/myenv/lib/python3.10/multiprocessing/resource_tracker.py:224: UserWarning: resource_tracker: There appear to be 1 leaked shared_memory objects to clean up at shutdown
  warnings.warn('resource_tracker: There appear to be %d '
/home/hkngae/anaconda3/envs/myenv/lib/python3.10/site-packages/vllm/connections.py:8: RuntimeWarning: Failed to read commit hash:
No module named 'vllm._version'
  from vllm.version import __version__ as VLLM_VERSION
/home/hkngae/anaconda3/envs/myenv/lib/python3.10/site-packages/vllm/connections.py:8: RuntimeWarning: Failed to read commit hash:
No module named 'vllm._version'
  from vllm.version import __version__ as VLLM_VERSION
/home/hkngae/anaconda3/envs/myenv/lib/python3.10/site-packages/vllm/connections.py:8: RuntimeWarning: Failed to read commit hash:
No module named 'vllm._version'
  from vllm.version import __version__ as VLLM_VERSION
/home/hkngae/anaconda3/envs/myenv/lib/python3.10/site-packages/vllm/connections.py:8: RuntimeWarning: Failed to read commit hash:
No module named 'vllm._version'
  from vllm.version import __version__ as VLLM_VERSION
/home/hkngae/anaconda3/envs/myenv/lib/python3.10/site-packages/vllm/connections.py:8: RuntimeWarning: Failed to read commit hash:
No module named 'vllm._version'
  from vllm.version import __version__ as VLLM_VERSION
Loading safetensors checkpoint shards:   0% Completed | 0/4 [00:00<?, ?it/s]
Loading safetensors checkpoint shards:  25% Completed | 1/4 [00:00<00:01,  2.05it/s]
Loading safetensors checkpoint shards:  50% Completed | 2/4 [00:00<00:01,  2.00it/s]
Loading safetensors checkpoint shards:  75% Completed | 3/4 [00:01<00:00,  2.99it/s]
Loading safetensors checkpoint shards: 100% Completed | 4/4 [00:01<00:00,  2.60it/s]
Loading safetensors checkpoint shards: 100% Completed | 4/4 [00:01<00:00,  2.50it/s]

INFO:     Started server process [1243321]
INFO:     Waiting for application startup.
INFO:     Application startup complete.
INFO:     Uvicorn running on socket ('0.0.0.0', 8000) (Press CTRL+C to quit)
Process SpawnProcess-1:
Traceback (most recent call last):
  File "/home/hkngae/anaconda3/envs/myenv/lib/python3.10/multiprocessing/process.py", line 314, in _bootstrap
    self.run()
  File "/home/hkngae/anaconda3/envs/myenv/lib/python3.10/multiprocessing/process.py", line 108, in run
    self._target(*self._args, **self._kwargs)
  File "/home/hkngae/anaconda3/envs/myenv/lib/python3.10/site-packages/vllm/engine/multiprocessing/engine.py", line 395, in run_mp_engine
    engine.start()
  File "/home/hkngae/anaconda3/envs/myenv/lib/python3.10/site-packages/vllm/engine/multiprocessing/engine.py", line 165, in start
    self.cleanup()
  File "/home/hkngae/anaconda3/envs/myenv/lib/python3.10/site-packages/vllm/engine/multiprocessing/engine.py", line 388, in signal_handler
    raise KeyboardInterrupt("MQLLMEngine terminated")
KeyboardInterrupt: MQLLMEngine terminated
INFO:     Shutting down
INFO:     Waiting for application shutdown.
INFO:     Application shutdown complete.
/home/hkngae/anaconda3/envs/myenv/lib/python3.10/multiprocessing/resource_tracker.py:224: UserWarning: resource_tracker: There appear to be 3 leaked semaphore objects to clean up at shutdown
  warnings.warn('resource_tracker: There appear to be %d '
/home/hkngae/anaconda3/envs/myenv/lib/python3.10/multiprocessing/resource_tracker.py:224: UserWarning: resource_tracker: There appear to be 1 leaked shared_memory objects to clean up at shutdown
  warnings.warn('resource_tracker: There appear to be %d '
/home/hkngae/anaconda3/envs/myenv/lib/python3.10/site-packages/vllm/connections.py:8: RuntimeWarning: Failed to read commit hash:
No module named 'vllm._version'
  from vllm.version import __version__ as VLLM_VERSION
/home/hkngae/anaconda3/envs/myenv/lib/python3.10/site-packages/vllm/connections.py:8: RuntimeWarning: Failed to read commit hash:
No module named 'vllm._version'
  from vllm.version import __version__ as VLLM_VERSION
/home/hkngae/anaconda3/envs/myenv/lib/python3.10/site-packages/vllm/connections.py:8: RuntimeWarning: Failed to read commit hash:
No module named 'vllm._version'
  from vllm.version import __version__ as VLLM_VERSION
/home/hkngae/anaconda3/envs/myenv/lib/python3.10/site-packages/vllm/connections.py:8: RuntimeWarning: Failed to read commit hash:
No module named 'vllm._version'
  from vllm.version import __version__ as VLLM_VERSION
/home/hkngae/anaconda3/envs/myenv/lib/python3.10/site-packages/vllm/connections.py:8: RuntimeWarning: Failed to read commit hash:
No module named 'vllm._version'
  from vllm.version import __version__ as VLLM_VERSION
Loading safetensors checkpoint shards:   0% Completed | 0/4 [00:00<?, ?it/s]
Loading safetensors checkpoint shards:  25% Completed | 1/4 [00:00<00:01,  1.98it/s]
Loading safetensors checkpoint shards:  50% Completed | 2/4 [00:00<00:00,  2.04it/s]
Loading safetensors checkpoint shards:  75% Completed | 3/4 [00:01<00:00,  3.11it/s]
Loading safetensors checkpoint shards: 100% Completed | 4/4 [00:01<00:00,  2.93it/s]
Loading safetensors checkpoint shards: 100% Completed | 4/4 [00:01<00:00,  2.71it/s]

INFO:     Started server process [1245312]
INFO:     Waiting for application startup.
INFO:     Application startup complete.
INFO:     Uvicorn running on socket ('0.0.0.0', 8000) (Press CTRL+C to quit)
Process SpawnProcess-1:
Traceback (most recent call last):
  File "/home/hkngae/anaconda3/envs/myenv/lib/python3.10/multiprocessing/process.py", line 314, in _bootstrap
    self.run()
  File "/home/hkngae/anaconda3/envs/myenv/lib/python3.10/multiprocessing/process.py", line 108, in run
    self._target(*self._args, **self._kwargs)
  File "/home/hkngae/anaconda3/envs/myenv/lib/python3.10/site-packages/vllm/engine/multiprocessing/engine.py", line 395, in run_mp_engine
    engine.start()
  File "/home/hkngae/anaconda3/envs/myenv/lib/python3.10/site-packages/vllm/engine/multiprocessing/engine.py", line 165, in start
    self.cleanup()
  File "/home/hkngae/anaconda3/envs/myenv/lib/python3.10/site-packages/vllm/engine/multiprocessing/engine.py", line 388, in signal_handler
    raise KeyboardInterrupt("MQLLMEngine terminated")
KeyboardInterrupt: MQLLMEngine terminated
INFO:     Shutting down
INFO:     Waiting for application shutdown.
INFO:     Application shutdown complete.
/home/hkngae/anaconda3/envs/myenv/lib/python3.10/multiprocessing/resource_tracker.py:224: UserWarning: resource_tracker: There appear to be 3 leaked semaphore objects to clean up at shutdown
  warnings.warn('resource_tracker: There appear to be %d '
/home/hkngae/anaconda3/envs/myenv/lib/python3.10/multiprocessing/resource_tracker.py:224: UserWarning: resource_tracker: There appear to be 1 leaked shared_memory objects to clean up at shutdown
  warnings.warn('resource_tracker: There appear to be %d '
/home/hkngae/anaconda3/envs/myenv/lib/python3.10/site-packages/vllm/connections.py:8: RuntimeWarning: Failed to read commit hash:
No module named 'vllm._version'
  from vllm.version import __version__ as VLLM_VERSION
/home/hkngae/anaconda3/envs/myenv/lib/python3.10/site-packages/vllm/connections.py:8: RuntimeWarning: Failed to read commit hash:
No module named 'vllm._version'
  from vllm.version import __version__ as VLLM_VERSION
/home/hkngae/anaconda3/envs/myenv/lib/python3.10/site-packages/vllm/connections.py:8: RuntimeWarning: Failed to read commit hash:
No module named 'vllm._version'
  from vllm.version import __version__ as VLLM_VERSION
/home/hkngae/anaconda3/envs/myenv/lib/python3.10/site-packages/vllm/connections.py:8: RuntimeWarning: Failed to read commit hash:
No module named 'vllm._version'
  from vllm.version import __version__ as VLLM_VERSION
/home/hkngae/anaconda3/envs/myenv/lib/python3.10/site-packages/vllm/connections.py:8: RuntimeWarning: Failed to read commit hash:
No module named 'vllm._version'
  from vllm.version import __version__ as VLLM_VERSION
Loading safetensors checkpoint shards:   0% Completed | 0/4 [00:00<?, ?it/s]
Loading safetensors checkpoint shards:  25% Completed | 1/4 [00:00<00:01,  1.92it/s]
Loading safetensors checkpoint shards:  50% Completed | 2/4 [00:01<00:01,  1.92it/s]
Loading safetensors checkpoint shards:  75% Completed | 3/4 [00:01<00:00,  2.92it/s]
Loading safetensors checkpoint shards: 100% Completed | 4/4 [00:01<00:00,  2.70it/s]
Loading safetensors checkpoint shards: 100% Completed | 4/4 [00:01<00:00,  2.53it/s]

INFO:     Started server process [1247511]
INFO:     Waiting for application startup.
INFO:     Application startup complete.
INFO:     Uvicorn running on socket ('0.0.0.0', 8000) (Press CTRL+C to quit)
Process SpawnProcess-1:
Traceback (most recent call last):
  File "/home/hkngae/anaconda3/envs/myenv/lib/python3.10/multiprocessing/process.py", line 314, in _bootstrap
    self.run()
  File "/home/hkngae/anaconda3/envs/myenv/lib/python3.10/multiprocessing/process.py", line 108, in run
    self._target(*self._args, **self._kwargs)
  File "/home/hkngae/anaconda3/envs/myenv/lib/python3.10/site-packages/vllm/engine/multiprocessing/engine.py", line 395, in run_mp_engine
    engine.start()
  File "/home/hkngae/anaconda3/envs/myenv/lib/python3.10/site-packages/vllm/engine/multiprocessing/engine.py", line 165, in start
    self.cleanup()
  File "/home/hkngae/anaconda3/envs/myenv/lib/python3.10/site-packages/vllm/engine/multiprocessing/engine.py", line 388, in signal_handler
    raise KeyboardInterrupt("MQLLMEngine terminated")
KeyboardInterrupt: MQLLMEngine terminated
INFO:     Shutting down
INFO:     Waiting for application shutdown.
INFO:     Application shutdown complete.
/home/hkngae/anaconda3/envs/myenv/lib/python3.10/multiprocessing/resource_tracker.py:224: UserWarning: resource_tracker: There appear to be 3 leaked semaphore objects to clean up at shutdown
  warnings.warn('resource_tracker: There appear to be %d '
/home/hkngae/anaconda3/envs/myenv/lib/python3.10/multiprocessing/resource_tracker.py:224: UserWarning: resource_tracker: There appear to be 1 leaked shared_memory objects to clean up at shutdown
  warnings.warn('resource_tracker: There appear to be %d '
/home/hkngae/anaconda3/envs/myenv/lib/python3.10/site-packages/vllm/connections.py:8: RuntimeWarning: Failed to read commit hash:
No module named 'vllm._version'
  from vllm.version import __version__ as VLLM_VERSION
/home/hkngae/anaconda3/envs/myenv/lib/python3.10/site-packages/vllm/connections.py:8: RuntimeWarning: Failed to read commit hash:
No module named 'vllm._version'
  from vllm.version import __version__ as VLLM_VERSION
/home/hkngae/anaconda3/envs/myenv/lib/python3.10/site-packages/vllm/connections.py:8: RuntimeWarning: Failed to read commit hash:
No module named 'vllm._version'
  from vllm.version import __version__ as VLLM_VERSION
/home/hkngae/anaconda3/envs/myenv/lib/python3.10/site-packages/vllm/connections.py:8: RuntimeWarning: Failed to read commit hash:
No module named 'vllm._version'
  from vllm.version import __version__ as VLLM_VERSION
/home/hkngae/anaconda3/envs/myenv/lib/python3.10/site-packages/vllm/connections.py:8: RuntimeWarning: Failed to read commit hash:
No module named 'vllm._version'
  from vllm.version import __version__ as VLLM_VERSION
Loading safetensors checkpoint shards:   0% Completed | 0/4 [00:00<?, ?it/s]
Loading safetensors checkpoint shards:  25% Completed | 1/4 [00:00<00:01,  2.22it/s]
Loading safetensors checkpoint shards:  50% Completed | 2/4 [00:00<00:00,  2.17it/s]
Loading safetensors checkpoint shards:  75% Completed | 3/4 [00:01<00:00,  3.23it/s]
Loading safetensors checkpoint shards: 100% Completed | 4/4 [00:01<00:00,  2.72it/s]
Loading safetensors checkpoint shards: 100% Completed | 4/4 [00:01<00:00,  2.66it/s]

INFO:     Started server process [1250421]
INFO:     Waiting for application startup.
INFO:     Application startup complete.
INFO:     Uvicorn running on socket ('0.0.0.0', 8000) (Press CTRL+C to quit)
Process SpawnProcess-1:
Traceback (most recent call last):
  File "/home/hkngae/anaconda3/envs/myenv/lib/python3.10/multiprocessing/process.py", line 314, in _bootstrap
    self.run()
  File "/home/hkngae/anaconda3/envs/myenv/lib/python3.10/multiprocessing/process.py", line 108, in run
    self._target(*self._args, **self._kwargs)
  File "/home/hkngae/anaconda3/envs/myenv/lib/python3.10/site-packages/vllm/engine/multiprocessing/engine.py", line 395, in run_mp_engine
    engine.start()
  File "/home/hkngae/anaconda3/envs/myenv/lib/python3.10/site-packages/vllm/engine/multiprocessing/engine.py", line 165, in start
    self.cleanup()
  File "/home/hkngae/anaconda3/envs/myenv/lib/python3.10/site-packages/vllm/engine/multiprocessing/engine.py", line 388, in signal_handler
    raise KeyboardInterrupt("MQLLMEngine terminated")
KeyboardInterrupt: MQLLMEngine terminated
INFO:     Shutting down
INFO:     Waiting for application shutdown.
INFO:     Application shutdown complete.
/home/hkngae/anaconda3/envs/myenv/lib/python3.10/multiprocessing/resource_tracker.py:224: UserWarning: resource_tracker: There appear to be 3 leaked semaphore objects to clean up at shutdown
  warnings.warn('resource_tracker: There appear to be %d '
/home/hkngae/anaconda3/envs/myenv/lib/python3.10/multiprocessing/resource_tracker.py:224: UserWarning: resource_tracker: There appear to be 1 leaked shared_memory objects to clean up at shutdown
  warnings.warn('resource_tracker: There appear to be %d '
/home/hkngae/anaconda3/envs/myenv/lib/python3.10/site-packages/vllm/connections.py:8: RuntimeWarning: Failed to read commit hash:
No module named 'vllm._version'
  from vllm.version import __version__ as VLLM_VERSION
/home/hkngae/anaconda3/envs/myenv/lib/python3.10/site-packages/vllm/connections.py:8: RuntimeWarning: Failed to read commit hash:
No module named 'vllm._version'
  from vllm.version import __version__ as VLLM_VERSION
/home/hkngae/anaconda3/envs/myenv/lib/python3.10/site-packages/vllm/connections.py:8: RuntimeWarning: Failed to read commit hash:
No module named 'vllm._version'
  from vllm.version import __version__ as VLLM_VERSION
/home/hkngae/anaconda3/envs/myenv/lib/python3.10/site-packages/vllm/connections.py:8: RuntimeWarning: Failed to read commit hash:
No module named 'vllm._version'
  from vllm.version import __version__ as VLLM_VERSION
/home/hkngae/anaconda3/envs/myenv/lib/python3.10/site-packages/vllm/connections.py:8: RuntimeWarning: Failed to read commit hash:
No module named 'vllm._version'
  from vllm.version import __version__ as VLLM_VERSION
Loading safetensors checkpoint shards:   0% Completed | 0/4 [00:00<?, ?it/s]
Loading safetensors checkpoint shards:  25% Completed | 1/4 [00:00<00:01,  1.93it/s]
Loading safetensors checkpoint shards:  50% Completed | 2/4 [00:01<00:01,  1.90it/s]
Loading safetensors checkpoint shards:  75% Completed | 3/4 [00:01<00:00,  2.85it/s]
Loading safetensors checkpoint shards: 100% Completed | 4/4 [00:01<00:00,  2.64it/s]
Loading safetensors checkpoint shards: 100% Completed | 4/4 [00:01<00:00,  2.48it/s]

INFO:     Started server process [1254035]
INFO:     Waiting for application startup.
INFO:     Application startup complete.
INFO:     Uvicorn running on socket ('0.0.0.0', 8000) (Press CTRL+C to quit)
INFO:     Shutting down
INFO:     Waiting for application shutdown.
INFO:     Application shutdown complete.
INFO:     Finished server process [1254035]
/home/hkngae/anaconda3/envs/myenv/lib/python3.10/multiprocessing/resource_tracker.py:224: UserWarning: resource_tracker: There appear to be 16 leaked semaphore objects to clean up at shutdown
  warnings.warn('resource_tracker: There appear to be %d '
/home/hkngae/anaconda3/envs/myenv/lib/python3.10/multiprocessing/resource_tracker.py:224: UserWarning: resource_tracker: There appear to be 1 leaked shared_memory objects to clean up at shutdown
  warnings.warn('resource_tracker: There appear to be %d '
