/home/hkngae/anaconda3/envs/myenv/lib/python3.10/site-packages/vllm/connections.py:8: RuntimeWarning: Failed to read commit hash:
No module named 'vllm._version'
  from vllm.version import __version__ as VLLM_VERSION
/home/hkngae/anaconda3/envs/myenv/lib/python3.10/site-packages/vllm/connections.py:8: RuntimeWarning: Failed to read commit hash:
No module named 'vllm._version'
  from vllm.version import __version__ as VLLM_VERSION
/home/hkngae/anaconda3/envs/myenv/lib/python3.10/site-packages/vllm/connections.py:8: RuntimeWarning: Failed to read commit hash:
No module named 'vllm._version'
  from vllm.version import __version__ as VLLM_VERSION
/home/hkngae/anaconda3/envs/myenv/lib/python3.10/site-packages/vllm/connections.py:8: RuntimeWarning: Failed to read commit hash:
No module named 'vllm._version'
  from vllm.version import __version__ as VLLM_VERSION
/home/hkngae/anaconda3/envs/myenv/lib/python3.10/site-packages/vllm/connections.py:8: RuntimeWarning: Failed to read commit hash:
No module named 'vllm._version'
  from vllm.version import __version__ as VLLM_VERSION
Loading safetensors checkpoint shards:   0% Completed | 0/4 [00:00<?, ?it/s]
Loading safetensors checkpoint shards:  25% Completed | 1/4 [00:00<00:01,  1.74it/s]
Loading safetensors checkpoint shards:  50% Completed | 2/4 [00:01<00:01,  1.70it/s]
Loading safetensors checkpoint shards:  75% Completed | 3/4 [00:01<00:00,  2.57it/s]
Loading safetensors checkpoint shards: 100% Completed | 4/4 [00:01<00:00,  2.32it/s]
Loading safetensors checkpoint shards: 100% Completed | 4/4 [00:01<00:00,  2.19it/s]

INFO:     Started server process [1283066]
INFO:     Waiting for application startup.
INFO:     Application startup complete.
INFO:     Uvicorn running on socket ('0.0.0.0', 8000) (Press CTRL+C to quit)
Process SpawnProcess-1:
Traceback (most recent call last):
  File "/home/hkngae/anaconda3/envs/myenv/lib/python3.10/multiprocessing/process.py", line 314, in _bootstrap
    self.run()
  File "/home/hkngae/anaconda3/envs/myenv/lib/python3.10/multiprocessing/process.py", line 108, in run
    self._target(*self._args, **self._kwargs)
  File "/home/hkngae/anaconda3/envs/myenv/lib/python3.10/site-packages/vllm/engine/multiprocessing/engine.py", line 395, in run_mp_engine
    engine.start()
  File "/home/hkngae/anaconda3/envs/myenv/lib/python3.10/site-packages/vllm/engine/multiprocessing/engine.py", line 165, in start
    self.cleanup()
  File "/home/hkngae/anaconda3/envs/myenv/lib/python3.10/site-packages/vllm/engine/multiprocessing/engine.py", line 388, in signal_handler
    raise KeyboardInterrupt("MQLLMEngine terminated")
KeyboardInterrupt: MQLLMEngine terminated
INFO:     Shutting down
INFO:     Waiting for application shutdown.
INFO:     Application shutdown complete.
/home/hkngae/anaconda3/envs/myenv/lib/python3.10/multiprocessing/resource_tracker.py:224: UserWarning: resource_tracker: There appear to be 3 leaked semaphore objects to clean up at shutdown
  warnings.warn('resource_tracker: There appear to be %d '
/home/hkngae/anaconda3/envs/myenv/lib/python3.10/multiprocessing/resource_tracker.py:224: UserWarning: resource_tracker: There appear to be 1 leaked shared_memory objects to clean up at shutdown
  warnings.warn('resource_tracker: There appear to be %d '
/home/hkngae/anaconda3/envs/myenv/lib/python3.10/site-packages/vllm/connections.py:8: RuntimeWarning: Failed to read commit hash:
No module named 'vllm._version'
  from vllm.version import __version__ as VLLM_VERSION
/home/hkngae/anaconda3/envs/myenv/lib/python3.10/site-packages/vllm/connections.py:8: RuntimeWarning: Failed to read commit hash:
No module named 'vllm._version'
  from vllm.version import __version__ as VLLM_VERSION
/home/hkngae/anaconda3/envs/myenv/lib/python3.10/site-packages/vllm/connections.py:8: RuntimeWarning: Failed to read commit hash:
No module named 'vllm._version'
  from vllm.version import __version__ as VLLM_VERSION
/home/hkngae/anaconda3/envs/myenv/lib/python3.10/site-packages/vllm/connections.py:8: RuntimeWarning: Failed to read commit hash:
No module named 'vllm._version'
  from vllm.version import __version__ as VLLM_VERSION
/home/hkngae/anaconda3/envs/myenv/lib/python3.10/site-packages/vllm/connections.py:8: RuntimeWarning: Failed to read commit hash:
No module named 'vllm._version'
  from vllm.version import __version__ as VLLM_VERSION
Loading safetensors checkpoint shards:   0% Completed | 0/4 [00:00<?, ?it/s]
Loading safetensors checkpoint shards:  25% Completed | 1/4 [00:00<00:01,  2.04it/s]
Loading safetensors checkpoint shards:  50% Completed | 2/4 [00:00<00:00,  2.12it/s]
Loading safetensors checkpoint shards:  75% Completed | 3/4 [00:01<00:00,  3.19it/s]
Loading safetensors checkpoint shards: 100% Completed | 4/4 [00:01<00:00,  2.94it/s]
Loading safetensors checkpoint shards: 100% Completed | 4/4 [00:01<00:00,  2.75it/s]

INFO:     Started server process [1284785]
INFO:     Waiting for application startup.
INFO:     Application startup complete.
INFO:     Uvicorn running on socket ('0.0.0.0', 8000) (Press CTRL+C to quit)
Process SpawnProcess-1:
Traceback (most recent call last):
  File "/home/hkngae/anaconda3/envs/myenv/lib/python3.10/multiprocessing/process.py", line 314, in _bootstrap
    self.run()
  File "/home/hkngae/anaconda3/envs/myenv/lib/python3.10/multiprocessing/process.py", line 108, in run
    self._target(*self._args, **self._kwargs)
  File "/home/hkngae/anaconda3/envs/myenv/lib/python3.10/site-packages/vllm/engine/multiprocessing/engine.py", line 395, in run_mp_engine
    engine.start()
  File "/home/hkngae/anaconda3/envs/myenv/lib/python3.10/site-packages/vllm/engine/multiprocessing/engine.py", line 165, in start
    self.cleanup()
  File "/home/hkngae/anaconda3/envs/myenv/lib/python3.10/site-packages/vllm/engine/multiprocessing/engine.py", line 388, in signal_handler
    raise KeyboardInterrupt("MQLLMEngine terminated")
KeyboardInterrupt: MQLLMEngine terminated
INFO:     Shutting down
INFO:     Waiting for application shutdown.
INFO:     Application shutdown complete.
/home/hkngae/anaconda3/envs/myenv/lib/python3.10/multiprocessing/resource_tracker.py:224: UserWarning: resource_tracker: There appear to be 3 leaked semaphore objects to clean up at shutdown
  warnings.warn('resource_tracker: There appear to be %d '
/home/hkngae/anaconda3/envs/myenv/lib/python3.10/multiprocessing/resource_tracker.py:224: UserWarning: resource_tracker: There appear to be 1 leaked shared_memory objects to clean up at shutdown
  warnings.warn('resource_tracker: There appear to be %d '
/home/hkngae/anaconda3/envs/myenv/lib/python3.10/site-packages/vllm/connections.py:8: RuntimeWarning: Failed to read commit hash:
No module named 'vllm._version'
  from vllm.version import __version__ as VLLM_VERSION
/home/hkngae/anaconda3/envs/myenv/lib/python3.10/site-packages/vllm/connections.py:8: RuntimeWarning: Failed to read commit hash:
No module named 'vllm._version'
  from vllm.version import __version__ as VLLM_VERSION
/home/hkngae/anaconda3/envs/myenv/lib/python3.10/site-packages/vllm/connections.py:8: RuntimeWarning: Failed to read commit hash:
No module named 'vllm._version'
  from vllm.version import __version__ as VLLM_VERSION
/home/hkngae/anaconda3/envs/myenv/lib/python3.10/site-packages/vllm/connections.py:8: RuntimeWarning: Failed to read commit hash:
No module named 'vllm._version'
  from vllm.version import __version__ as VLLM_VERSION
/home/hkngae/anaconda3/envs/myenv/lib/python3.10/site-packages/vllm/connections.py:8: RuntimeWarning: Failed to read commit hash:
No module named 'vllm._version'
  from vllm.version import __version__ as VLLM_VERSION
Loading safetensors checkpoint shards:   0% Completed | 0/4 [00:00<?, ?it/s]
Loading safetensors checkpoint shards:  25% Completed | 1/4 [00:00<00:01,  2.07it/s]
Loading safetensors checkpoint shards:  50% Completed | 2/4 [00:01<00:01,  1.97it/s]
Loading safetensors checkpoint shards:  75% Completed | 3/4 [00:01<00:00,  2.93it/s]
Loading safetensors checkpoint shards: 100% Completed | 4/4 [00:01<00:00,  2.52it/s]
Loading safetensors checkpoint shards: 100% Completed | 4/4 [00:01<00:00,  2.45it/s]

INFO:     Started server process [1286579]
INFO:     Waiting for application startup.
INFO:     Application startup complete.
INFO:     Uvicorn running on socket ('0.0.0.0', 8000) (Press CTRL+C to quit)
Process SpawnProcess-1:
Traceback (most recent call last):
  File "/home/hkngae/anaconda3/envs/myenv/lib/python3.10/multiprocessing/process.py", line 314, in _bootstrap
    self.run()
  File "/home/hkngae/anaconda3/envs/myenv/lib/python3.10/multiprocessing/process.py", line 108, in run
    self._target(*self._args, **self._kwargs)
  File "/home/hkngae/anaconda3/envs/myenv/lib/python3.10/site-packages/vllm/engine/multiprocessing/engine.py", line 395, in run_mp_engine
    engine.start()
  File "/home/hkngae/anaconda3/envs/myenv/lib/python3.10/site-packages/vllm/engine/multiprocessing/engine.py", line 165, in start
    self.cleanup()
  File "/home/hkngae/anaconda3/envs/myenv/lib/python3.10/site-packages/vllm/engine/multiprocessing/engine.py", line 388, in signal_handler
    raise KeyboardInterrupt("MQLLMEngine terminated")
KeyboardInterrupt: MQLLMEngine terminated
INFO:     Shutting down
INFO:     Waiting for application shutdown.
INFO:     Application shutdown complete.
/home/hkngae/anaconda3/envs/myenv/lib/python3.10/multiprocessing/resource_tracker.py:224: UserWarning: resource_tracker: There appear to be 3 leaked semaphore objects to clean up at shutdown
  warnings.warn('resource_tracker: There appear to be %d '
/home/hkngae/anaconda3/envs/myenv/lib/python3.10/multiprocessing/resource_tracker.py:224: UserWarning: resource_tracker: There appear to be 1 leaked shared_memory objects to clean up at shutdown
  warnings.warn('resource_tracker: There appear to be %d '
/home/hkngae/anaconda3/envs/myenv/lib/python3.10/site-packages/vllm/connections.py:8: RuntimeWarning: Failed to read commit hash:
No module named 'vllm._version'
  from vllm.version import __version__ as VLLM_VERSION
/home/hkngae/anaconda3/envs/myenv/lib/python3.10/site-packages/vllm/connections.py:8: RuntimeWarning: Failed to read commit hash:
No module named 'vllm._version'
  from vllm.version import __version__ as VLLM_VERSION
/home/hkngae/anaconda3/envs/myenv/lib/python3.10/site-packages/vllm/connections.py:8: RuntimeWarning: Failed to read commit hash:
No module named 'vllm._version'
  from vllm.version import __version__ as VLLM_VERSION
/home/hkngae/anaconda3/envs/myenv/lib/python3.10/site-packages/vllm/connections.py:8: RuntimeWarning: Failed to read commit hash:
No module named 'vllm._version'
  from vllm.version import __version__ as VLLM_VERSION
/home/hkngae/anaconda3/envs/myenv/lib/python3.10/site-packages/vllm/connections.py:8: RuntimeWarning: Failed to read commit hash:
No module named 'vllm._version'
  from vllm.version import __version__ as VLLM_VERSION
Loading safetensors checkpoint shards:   0% Completed | 0/4 [00:00<?, ?it/s]
Loading safetensors checkpoint shards:  25% Completed | 1/4 [00:00<00:01,  1.72it/s]
Loading safetensors checkpoint shards:  50% Completed | 2/4 [00:01<00:01,  1.88it/s]
Loading safetensors checkpoint shards:  75% Completed | 3/4 [00:01<00:00,  2.88it/s]
Loading safetensors checkpoint shards: 100% Completed | 4/4 [00:01<00:00,  2.78it/s]
Loading safetensors checkpoint shards: 100% Completed | 4/4 [00:01<00:00,  2.52it/s]

INFO:     Started server process [1288694]
INFO:     Waiting for application startup.
INFO:     Application startup complete.
INFO:     Uvicorn running on socket ('0.0.0.0', 8000) (Press CTRL+C to quit)
Process SpawnProcess-1:
Traceback (most recent call last):
  File "/home/hkngae/anaconda3/envs/myenv/lib/python3.10/multiprocessing/process.py", line 314, in _bootstrap
    self.run()
  File "/home/hkngae/anaconda3/envs/myenv/lib/python3.10/multiprocessing/process.py", line 108, in run
    self._target(*self._args, **self._kwargs)
  File "/home/hkngae/anaconda3/envs/myenv/lib/python3.10/site-packages/vllm/engine/multiprocessing/engine.py", line 395, in run_mp_engine
    engine.start()
  File "/home/hkngae/anaconda3/envs/myenv/lib/python3.10/site-packages/vllm/engine/multiprocessing/engine.py", line 165, in start
    self.cleanup()
  File "/home/hkngae/anaconda3/envs/myenv/lib/python3.10/site-packages/vllm/engine/multiprocessing/engine.py", line 388, in signal_handler
    raise KeyboardInterrupt("MQLLMEngine terminated")
KeyboardInterrupt: MQLLMEngine terminated
INFO:     Shutting down
INFO:     Waiting for application shutdown.
INFO:     Application shutdown complete.
/home/hkngae/anaconda3/envs/myenv/lib/python3.10/multiprocessing/resource_tracker.py:224: UserWarning: resource_tracker: There appear to be 3 leaked semaphore objects to clean up at shutdown
  warnings.warn('resource_tracker: There appear to be %d '
/home/hkngae/anaconda3/envs/myenv/lib/python3.10/multiprocessing/resource_tracker.py:224: UserWarning: resource_tracker: There appear to be 1 leaked shared_memory objects to clean up at shutdown
  warnings.warn('resource_tracker: There appear to be %d '
/home/hkngae/anaconda3/envs/myenv/lib/python3.10/site-packages/vllm/connections.py:8: RuntimeWarning: Failed to read commit hash:
No module named 'vllm._version'
  from vllm.version import __version__ as VLLM_VERSION
/home/hkngae/anaconda3/envs/myenv/lib/python3.10/site-packages/vllm/connections.py:8: RuntimeWarning: Failed to read commit hash:
No module named 'vllm._version'
  from vllm.version import __version__ as VLLM_VERSION
/home/hkngae/anaconda3/envs/myenv/lib/python3.10/site-packages/vllm/connections.py:8: RuntimeWarning: Failed to read commit hash:
No module named 'vllm._version'
  from vllm.version import __version__ as VLLM_VERSION
/home/hkngae/anaconda3/envs/myenv/lib/python3.10/site-packages/vllm/connections.py:8: RuntimeWarning: Failed to read commit hash:
No module named 'vllm._version'
  from vllm.version import __version__ as VLLM_VERSION
/home/hkngae/anaconda3/envs/myenv/lib/python3.10/site-packages/vllm/connections.py:8: RuntimeWarning: Failed to read commit hash:
No module named 'vllm._version'
  from vllm.version import __version__ as VLLM_VERSION
Loading safetensors checkpoint shards:   0% Completed | 0/4 [00:00<?, ?it/s]
Loading safetensors checkpoint shards:  25% Completed | 1/4 [00:00<00:01,  2.36it/s]
Loading safetensors checkpoint shards:  50% Completed | 2/4 [00:00<00:00,  2.24it/s]
Loading safetensors checkpoint shards:  75% Completed | 3/4 [00:01<00:00,  3.29it/s]
Loading safetensors checkpoint shards: 100% Completed | 4/4 [00:01<00:00,  2.82it/s]
Loading safetensors checkpoint shards: 100% Completed | 4/4 [00:01<00:00,  2.75it/s]

INFO:     Started server process [1290802]
INFO:     Waiting for application startup.
INFO:     Application startup complete.
INFO:     Uvicorn running on socket ('0.0.0.0', 8000) (Press CTRL+C to quit)
Process SpawnProcess-1:
Traceback (most recent call last):
  File "/home/hkngae/anaconda3/envs/myenv/lib/python3.10/multiprocessing/process.py", line 314, in _bootstrap
    self.run()
  File "/home/hkngae/anaconda3/envs/myenv/lib/python3.10/multiprocessing/process.py", line 108, in run
    self._target(*self._args, **self._kwargs)
  File "/home/hkngae/anaconda3/envs/myenv/lib/python3.10/site-packages/vllm/engine/multiprocessing/engine.py", line 395, in run_mp_engine
    engine.start()
  File "/home/hkngae/anaconda3/envs/myenv/lib/python3.10/site-packages/vllm/engine/multiprocessing/engine.py", line 165, in start
    self.cleanup()
  File "/home/hkngae/anaconda3/envs/myenv/lib/python3.10/site-packages/vllm/engine/multiprocessing/engine.py", line 388, in signal_handler
    raise KeyboardInterrupt("MQLLMEngine terminated")
KeyboardInterrupt: MQLLMEngine terminated
INFO:     Shutting down
INFO:     Waiting for application shutdown.
INFO:     Application shutdown complete.
/home/hkngae/anaconda3/envs/myenv/lib/python3.10/multiprocessing/resource_tracker.py:224: UserWarning: resource_tracker: There appear to be 3 leaked semaphore objects to clean up at shutdown
  warnings.warn('resource_tracker: There appear to be %d '
/home/hkngae/anaconda3/envs/myenv/lib/python3.10/multiprocessing/resource_tracker.py:224: UserWarning: resource_tracker: There appear to be 1 leaked shared_memory objects to clean up at shutdown
  warnings.warn('resource_tracker: There appear to be %d '
/home/hkngae/anaconda3/envs/myenv/lib/python3.10/site-packages/vllm/connections.py:8: RuntimeWarning: Failed to read commit hash:
No module named 'vllm._version'
  from vllm.version import __version__ as VLLM_VERSION
/home/hkngae/anaconda3/envs/myenv/lib/python3.10/site-packages/vllm/connections.py:8: RuntimeWarning: Failed to read commit hash:
No module named 'vllm._version'
  from vllm.version import __version__ as VLLM_VERSION
/home/hkngae/anaconda3/envs/myenv/lib/python3.10/site-packages/vllm/connections.py:8: RuntimeWarning: Failed to read commit hash:
No module named 'vllm._version'
  from vllm.version import __version__ as VLLM_VERSION
/home/hkngae/anaconda3/envs/myenv/lib/python3.10/site-packages/vllm/connections.py:8: RuntimeWarning: Failed to read commit hash:
No module named 'vllm._version'
  from vllm.version import __version__ as VLLM_VERSION
/home/hkngae/anaconda3/envs/myenv/lib/python3.10/site-packages/vllm/connections.py:8: RuntimeWarning: Failed to read commit hash:
No module named 'vllm._version'
  from vllm.version import __version__ as VLLM_VERSION
Loading safetensors checkpoint shards:   0% Completed | 0/4 [00:00<?, ?it/s]
Loading safetensors checkpoint shards:  25% Completed | 1/4 [00:00<00:01,  1.84it/s]
Loading safetensors checkpoint shards:  50% Completed | 2/4 [00:01<00:01,  1.79it/s]
Loading safetensors checkpoint shards:  75% Completed | 3/4 [00:01<00:00,  2.69it/s]
Loading safetensors checkpoint shards: 100% Completed | 4/4 [00:01<00:00,  2.29it/s]
Loading safetensors checkpoint shards: 100% Completed | 4/4 [00:01<00:00,  2.23it/s]

INFO:     Started server process [1293305]
INFO:     Waiting for application startup.
INFO:     Application startup complete.
INFO:     Uvicorn running on socket ('0.0.0.0', 8000) (Press CTRL+C to quit)
Process SpawnProcess-1:
Traceback (most recent call last):
  File "/home/hkngae/anaconda3/envs/myenv/lib/python3.10/multiprocessing/process.py", line 314, in _bootstrap
    self.run()
  File "/home/hkngae/anaconda3/envs/myenv/lib/python3.10/multiprocessing/process.py", line 108, in run
    self._target(*self._args, **self._kwargs)
  File "/home/hkngae/anaconda3/envs/myenv/lib/python3.10/site-packages/vllm/engine/multiprocessing/engine.py", line 395, in run_mp_engine
    engine.start()
  File "/home/hkngae/anaconda3/envs/myenv/lib/python3.10/site-packages/vllm/engine/multiprocessing/engine.py", line 165, in start
    self.cleanup()
  File "/home/hkngae/anaconda3/envs/myenv/lib/python3.10/site-packages/vllm/engine/multiprocessing/engine.py", line 388, in signal_handler
    raise KeyboardInterrupt("MQLLMEngine terminated")
KeyboardInterrupt: MQLLMEngine terminated
INFO:     Shutting down
INFO:     Waiting for application shutdown.
INFO:     Application shutdown complete.
/home/hkngae/anaconda3/envs/myenv/lib/python3.10/multiprocessing/resource_tracker.py:224: UserWarning: resource_tracker: There appear to be 3 leaked semaphore objects to clean up at shutdown
  warnings.warn('resource_tracker: There appear to be %d '
/home/hkngae/anaconda3/envs/myenv/lib/python3.10/multiprocessing/resource_tracker.py:224: UserWarning: resource_tracker: There appear to be 1 leaked shared_memory objects to clean up at shutdown
  warnings.warn('resource_tracker: There appear to be %d '
/home/hkngae/anaconda3/envs/myenv/lib/python3.10/site-packages/vllm/connections.py:8: RuntimeWarning: Failed to read commit hash:
No module named 'vllm._version'
  from vllm.version import __version__ as VLLM_VERSION
/home/hkngae/anaconda3/envs/myenv/lib/python3.10/site-packages/vllm/connections.py:8: RuntimeWarning: Failed to read commit hash:
No module named 'vllm._version'
  from vllm.version import __version__ as VLLM_VERSION
/home/hkngae/anaconda3/envs/myenv/lib/python3.10/site-packages/vllm/connections.py:8: RuntimeWarning: Failed to read commit hash:
No module named 'vllm._version'
  from vllm.version import __version__ as VLLM_VERSION
/home/hkngae/anaconda3/envs/myenv/lib/python3.10/site-packages/vllm/connections.py:8: RuntimeWarning: Failed to read commit hash:
No module named 'vllm._version'
  from vllm.version import __version__ as VLLM_VERSION
/home/hkngae/anaconda3/envs/myenv/lib/python3.10/site-packages/vllm/connections.py:8: RuntimeWarning: Failed to read commit hash:
No module named 'vllm._version'
  from vllm.version import __version__ as VLLM_VERSION
Loading safetensors checkpoint shards:   0% Completed | 0/4 [00:00<?, ?it/s]
Loading safetensors checkpoint shards:  25% Completed | 1/4 [00:00<00:01,  2.08it/s]
Loading safetensors checkpoint shards:  50% Completed | 2/4 [00:00<00:00,  2.04it/s]
Loading safetensors checkpoint shards:  75% Completed | 3/4 [00:01<00:00,  3.08it/s]
Loading safetensors checkpoint shards: 100% Completed | 4/4 [00:01<00:00,  2.84it/s]
Loading safetensors checkpoint shards: 100% Completed | 4/4 [00:01<00:00,  2.66it/s]

INFO:     Started server process [1296931]
INFO:     Waiting for application startup.
INFO:     Application startup complete.
INFO:     Uvicorn running on socket ('0.0.0.0', 8000) (Press CTRL+C to quit)
Process SpawnProcess-1:
Traceback (most recent call last):
  File "/home/hkngae/anaconda3/envs/myenv/lib/python3.10/multiprocessing/process.py", line 314, in _bootstrap
    self.run()
  File "/home/hkngae/anaconda3/envs/myenv/lib/python3.10/multiprocessing/process.py", line 108, in run
    self._target(*self._args, **self._kwargs)
  File "/home/hkngae/anaconda3/envs/myenv/lib/python3.10/site-packages/vllm/engine/multiprocessing/engine.py", line 395, in run_mp_engine
    engine.start()
  File "/home/hkngae/anaconda3/envs/myenv/lib/python3.10/site-packages/vllm/engine/multiprocessing/engine.py", line 165, in start
    self.cleanup()
  File "/home/hkngae/anaconda3/envs/myenv/lib/python3.10/site-packages/vllm/engine/multiprocessing/engine.py", line 388, in signal_handler
    raise KeyboardInterrupt("MQLLMEngine terminated")
KeyboardInterrupt: MQLLMEngine terminated
INFO:     Shutting down
INFO:     Waiting for application shutdown.
INFO:     Application shutdown complete.
/home/hkngae/anaconda3/envs/myenv/lib/python3.10/multiprocessing/resource_tracker.py:224: UserWarning: resource_tracker: There appear to be 3 leaked semaphore objects to clean up at shutdown
  warnings.warn('resource_tracker: There appear to be %d '
/home/hkngae/anaconda3/envs/myenv/lib/python3.10/multiprocessing/resource_tracker.py:224: UserWarning: resource_tracker: There appear to be 1 leaked shared_memory objects to clean up at shutdown
  warnings.warn('resource_tracker: There appear to be %d '
