/home/hkngae/anaconda3/envs/myenv/lib/python3.10/site-packages/vllm/connections.py:8: RuntimeWarning: Failed to read commit hash:
No module named 'vllm._version'
  from vllm.version import __version__ as VLLM_VERSION
/home/hkngae/anaconda3/envs/myenv/lib/python3.10/site-packages/vllm/connections.py:8: RuntimeWarning: Failed to read commit hash:
No module named 'vllm._version'
  from vllm.version import __version__ as VLLM_VERSION
/home/hkngae/anaconda3/envs/myenv/lib/python3.10/site-packages/vllm/connections.py:8: RuntimeWarning: Failed to read commit hash:
No module named 'vllm._version'
  from vllm.version import __version__ as VLLM_VERSION
/home/hkngae/anaconda3/envs/myenv/lib/python3.10/site-packages/vllm/connections.py:8: RuntimeWarning: Failed to read commit hash:
No module named 'vllm._version'
  from vllm.version import __version__ as VLLM_VERSION
/home/hkngae/anaconda3/envs/myenv/lib/python3.10/site-packages/vllm/connections.py:8: RuntimeWarning: Failed to read commit hash:
No module named 'vllm._version'
  from vllm.version import __version__ as VLLM_VERSION
Loading safetensors checkpoint shards:   0% Completed | 0/4 [00:00<?, ?it/s]
Loading safetensors checkpoint shards:  25% Completed | 1/4 [00:00<00:01,  1.71it/s]
Loading safetensors checkpoint shards:  50% Completed | 2/4 [00:01<00:01,  1.71it/s]
Loading safetensors checkpoint shards:  75% Completed | 3/4 [00:01<00:00,  2.56it/s]
Loading safetensors checkpoint shards: 100% Completed | 4/4 [00:01<00:00,  2.22it/s]
Loading safetensors checkpoint shards: 100% Completed | 4/4 [00:01<00:00,  2.14it/s]

INFO:     Started server process [1103997]
INFO:     Waiting for application startup.
INFO:     Application startup complete.
INFO:     Uvicorn running on socket ('0.0.0.0', 8000) (Press CTRL+C to quit)
Process SpawnProcess-1:
Traceback (most recent call last):
  File "/home/hkngae/anaconda3/envs/myenv/lib/python3.10/multiprocessing/process.py", line 314, in _bootstrap
    self.run()
  File "/home/hkngae/anaconda3/envs/myenv/lib/python3.10/multiprocessing/process.py", line 108, in run
    self._target(*self._args, **self._kwargs)
  File "/home/hkngae/anaconda3/envs/myenv/lib/python3.10/site-packages/vllm/engine/multiprocessing/engine.py", line 395, in run_mp_engine
    engine.start()
  File "/home/hkngae/anaconda3/envs/myenv/lib/python3.10/site-packages/vllm/engine/multiprocessing/engine.py", line 165, in start
    self.cleanup()
  File "/home/hkngae/anaconda3/envs/myenv/lib/python3.10/site-packages/vllm/engine/multiprocessing/engine.py", line 388, in signal_handler
    raise KeyboardInterrupt("MQLLMEngine terminated")
KeyboardInterrupt: MQLLMEngine terminated
INFO:     Shutting down
INFO:     Waiting for application shutdown.
INFO:     Application shutdown complete.
/home/hkngae/anaconda3/envs/myenv/lib/python3.10/site-packages/vllm/connections.py:8: RuntimeWarning: Failed to read commit hash:
No module named 'vllm._version'
  from vllm.version import __version__ as VLLM_VERSION
/home/hkngae/anaconda3/envs/myenv/lib/python3.10/multiprocessing/resource_tracker.py:224: UserWarning: resource_tracker: There appear to be 3 leaked semaphore objects to clean up at shutdown
  warnings.warn('resource_tracker: There appear to be %d '
/home/hkngae/anaconda3/envs/myenv/lib/python3.10/multiprocessing/resource_tracker.py:224: UserWarning: resource_tracker: There appear to be 1 leaked shared_memory objects to clean up at shutdown
  warnings.warn('resource_tracker: There appear to be %d '
/home/hkngae/anaconda3/envs/myenv/lib/python3.10/site-packages/vllm/connections.py:8: RuntimeWarning: Failed to read commit hash:
No module named 'vllm._version'
  from vllm.version import __version__ as VLLM_VERSION
/home/hkngae/anaconda3/envs/myenv/lib/python3.10/site-packages/vllm/connections.py:8: RuntimeWarning: Failed to read commit hash:
No module named 'vllm._version'
  from vllm.version import __version__ as VLLM_VERSION
/home/hkngae/anaconda3/envs/myenv/lib/python3.10/site-packages/vllm/connections.py:8: RuntimeWarning: Failed to read commit hash:
No module named 'vllm._version'
  from vllm.version import __version__ as VLLM_VERSION
/home/hkngae/anaconda3/envs/myenv/lib/python3.10/site-packages/vllm/connections.py:8: RuntimeWarning: Failed to read commit hash:
No module named 'vllm._version'
  from vllm.version import __version__ as VLLM_VERSION
Loading safetensors checkpoint shards:   0% Completed | 0/4 [00:00<?, ?it/s]
Loading safetensors checkpoint shards:  25% Completed | 1/4 [00:00<00:01,  2.12it/s]
Loading safetensors checkpoint shards:  50% Completed | 2/4 [00:00<00:00,  2.13it/s]
Loading safetensors checkpoint shards:  75% Completed | 3/4 [00:01<00:00,  3.20it/s]
Loading safetensors checkpoint shards: 100% Completed | 4/4 [00:01<00:00,  2.87it/s]
Loading safetensors checkpoint shards: 100% Completed | 4/4 [00:01<00:00,  2.72it/s]

INFO:     Started server process [1105635]
INFO:     Waiting for application startup.
INFO:     Application startup complete.
INFO:     Uvicorn running on socket ('0.0.0.0', 8000) (Press CTRL+C to quit)
Process SpawnProcess-1:
Traceback (most recent call last):
  File "/home/hkngae/anaconda3/envs/myenv/lib/python3.10/multiprocessing/process.py", line 314, in _bootstrap
    self.run()
  File "/home/hkngae/anaconda3/envs/myenv/lib/python3.10/multiprocessing/process.py", line 108, in run
    self._target(*self._args, **self._kwargs)
  File "/home/hkngae/anaconda3/envs/myenv/lib/python3.10/site-packages/vllm/engine/multiprocessing/engine.py", line 395, in run_mp_engine
    engine.start()
  File "/home/hkngae/anaconda3/envs/myenv/lib/python3.10/site-packages/vllm/engine/multiprocessing/engine.py", line 165, in start
    self.cleanup()
  File "/home/hkngae/anaconda3/envs/myenv/lib/python3.10/site-packages/vllm/engine/multiprocessing/engine.py", line 388, in signal_handler
    raise KeyboardInterrupt("MQLLMEngine terminated")
KeyboardInterrupt: MQLLMEngine terminated
INFO:     Shutting down
INFO:     Waiting for application shutdown.
INFO:     Application shutdown complete.
/home/hkngae/anaconda3/envs/myenv/lib/python3.10/site-packages/vllm/connections.py:8: RuntimeWarning: Failed to read commit hash:
No module named 'vllm._version'
  from vllm.version import __version__ as VLLM_VERSION
/home/hkngae/anaconda3/envs/myenv/lib/python3.10/multiprocessing/resource_tracker.py:224: UserWarning: resource_tracker: There appear to be 3 leaked semaphore objects to clean up at shutdown
  warnings.warn('resource_tracker: There appear to be %d '
/home/hkngae/anaconda3/envs/myenv/lib/python3.10/multiprocessing/resource_tracker.py:224: UserWarning: resource_tracker: There appear to be 1 leaked shared_memory objects to clean up at shutdown
  warnings.warn('resource_tracker: There appear to be %d '
/home/hkngae/anaconda3/envs/myenv/lib/python3.10/site-packages/vllm/connections.py:8: RuntimeWarning: Failed to read commit hash:
No module named 'vllm._version'
  from vllm.version import __version__ as VLLM_VERSION
/home/hkngae/anaconda3/envs/myenv/lib/python3.10/site-packages/vllm/connections.py:8: RuntimeWarning: Failed to read commit hash:
No module named 'vllm._version'
  from vllm.version import __version__ as VLLM_VERSION
/home/hkngae/anaconda3/envs/myenv/lib/python3.10/site-packages/vllm/connections.py:8: RuntimeWarning: Failed to read commit hash:
No module named 'vllm._version'
  from vllm.version import __version__ as VLLM_VERSION
/home/hkngae/anaconda3/envs/myenv/lib/python3.10/site-packages/vllm/connections.py:8: RuntimeWarning: Failed to read commit hash:
No module named 'vllm._version'
  from vllm.version import __version__ as VLLM_VERSION
Loading safetensors checkpoint shards:   0% Completed | 0/4 [00:00<?, ?it/s]
Loading safetensors checkpoint shards:  25% Completed | 1/4 [00:00<00:01,  1.95it/s]
Loading safetensors checkpoint shards:  50% Completed | 2/4 [00:01<00:01,  1.94it/s]
Loading safetensors checkpoint shards:  75% Completed | 3/4 [00:01<00:00,  2.94it/s]
Loading safetensors checkpoint shards: 100% Completed | 4/4 [00:01<00:00,  2.78it/s]
Loading safetensors checkpoint shards: 100% Completed | 4/4 [00:01<00:00,  2.58it/s]

INFO:     Started server process [1108356]
INFO:     Waiting for application startup.
INFO:     Application startup complete.
INFO:     Uvicorn running on socket ('0.0.0.0', 8000) (Press CTRL+C to quit)
Process SpawnProcess-1:
Traceback (most recent call last):
  File "/home/hkngae/anaconda3/envs/myenv/lib/python3.10/multiprocessing/process.py", line 314, in _bootstrap
    self.run()
  File "/home/hkngae/anaconda3/envs/myenv/lib/python3.10/multiprocessing/process.py", line 108, in run
    self._target(*self._args, **self._kwargs)
  File "/home/hkngae/anaconda3/envs/myenv/lib/python3.10/site-packages/vllm/engine/multiprocessing/engine.py", line 395, in run_mp_engine
    engine.start()
  File "/home/hkngae/anaconda3/envs/myenv/lib/python3.10/site-packages/vllm/engine/multiprocessing/engine.py", line 165, in start
    self.cleanup()
  File "/home/hkngae/anaconda3/envs/myenv/lib/python3.10/site-packages/vllm/engine/multiprocessing/engine.py", line 388, in signal_handler
    raise KeyboardInterrupt("MQLLMEngine terminated")
KeyboardInterrupt: MQLLMEngine terminated
INFO:     Shutting down
INFO:     Waiting for application shutdown.
INFO:     Application shutdown complete.
/home/hkngae/anaconda3/envs/myenv/lib/python3.10/site-packages/vllm/connections.py:8: RuntimeWarning: Failed to read commit hash:
No module named 'vllm._version'
  from vllm.version import __version__ as VLLM_VERSION
/home/hkngae/anaconda3/envs/myenv/lib/python3.10/multiprocessing/resource_tracker.py:224: UserWarning: resource_tracker: There appear to be 3 leaked semaphore objects to clean up at shutdown
  warnings.warn('resource_tracker: There appear to be %d '
/home/hkngae/anaconda3/envs/myenv/lib/python3.10/multiprocessing/resource_tracker.py:224: UserWarning: resource_tracker: There appear to be 1 leaked shared_memory objects to clean up at shutdown
  warnings.warn('resource_tracker: There appear to be %d '
/home/hkngae/anaconda3/envs/myenv/lib/python3.10/site-packages/vllm/connections.py:8: RuntimeWarning: Failed to read commit hash:
No module named 'vllm._version'
  from vllm.version import __version__ as VLLM_VERSION
/home/hkngae/anaconda3/envs/myenv/lib/python3.10/site-packages/vllm/connections.py:8: RuntimeWarning: Failed to read commit hash:
No module named 'vllm._version'
  from vllm.version import __version__ as VLLM_VERSION
/home/hkngae/anaconda3/envs/myenv/lib/python3.10/site-packages/vllm/connections.py:8: RuntimeWarning: Failed to read commit hash:
No module named 'vllm._version'
  from vllm.version import __version__ as VLLM_VERSION
/home/hkngae/anaconda3/envs/myenv/lib/python3.10/site-packages/vllm/connections.py:8: RuntimeWarning: Failed to read commit hash:
No module named 'vllm._version'
  from vllm.version import __version__ as VLLM_VERSION
Loading safetensors checkpoint shards:   0% Completed | 0/4 [00:00<?, ?it/s]
Loading safetensors checkpoint shards:  25% Completed | 1/4 [00:00<00:01,  2.27it/s]
Loading safetensors checkpoint shards:  50% Completed | 2/4 [00:00<00:00,  2.10it/s]
Loading safetensors checkpoint shards:  75% Completed | 3/4 [00:01<00:00,  3.15it/s]
Loading safetensors checkpoint shards: 100% Completed | 4/4 [00:01<00:00,  2.73it/s]
Loading safetensors checkpoint shards: 100% Completed | 4/4 [00:01<00:00,  2.64it/s]

INFO:     Started server process [1110351]
INFO:     Waiting for application startup.
INFO:     Application startup complete.
INFO:     Uvicorn running on socket ('0.0.0.0', 8000) (Press CTRL+C to quit)
Process SpawnProcess-1:
Traceback (most recent call last):
  File "/home/hkngae/anaconda3/envs/myenv/lib/python3.10/multiprocessing/process.py", line 314, in _bootstrap
    self.run()
  File "/home/hkngae/anaconda3/envs/myenv/lib/python3.10/multiprocessing/process.py", line 108, in run
    self._target(*self._args, **self._kwargs)
  File "/home/hkngae/anaconda3/envs/myenv/lib/python3.10/site-packages/vllm/engine/multiprocessing/engine.py", line 395, in run_mp_engine
    engine.start()
  File "/home/hkngae/anaconda3/envs/myenv/lib/python3.10/site-packages/vllm/engine/multiprocessing/engine.py", line 165, in start
    self.cleanup()
  File "/home/hkngae/anaconda3/envs/myenv/lib/python3.10/site-packages/vllm/engine/multiprocessing/engine.py", line 388, in signal_handler
    raise KeyboardInterrupt("MQLLMEngine terminated")
KeyboardInterrupt: MQLLMEngine terminated
INFO:     Shutting down
INFO:     Waiting for application shutdown.
INFO:     Application shutdown complete.
/home/hkngae/anaconda3/envs/myenv/lib/python3.10/multiprocessing/resource_tracker.py:224: UserWarning: resource_tracker: There appear to be 3 leaked semaphore objects to clean up at shutdown
  warnings.warn('resource_tracker: There appear to be %d '
/home/hkngae/anaconda3/envs/myenv/lib/python3.10/multiprocessing/resource_tracker.py:224: UserWarning: resource_tracker: There appear to be 1 leaked shared_memory objects to clean up at shutdown
  warnings.warn('resource_tracker: There appear to be %d '
/home/hkngae/anaconda3/envs/myenv/lib/python3.10/site-packages/vllm/connections.py:8: RuntimeWarning: Failed to read commit hash:
No module named 'vllm._version'
  from vllm.version import __version__ as VLLM_VERSION
/home/hkngae/anaconda3/envs/myenv/lib/python3.10/site-packages/vllm/connections.py:8: RuntimeWarning: Failed to read commit hash:
No module named 'vllm._version'
  from vllm.version import __version__ as VLLM_VERSION
/home/hkngae/anaconda3/envs/myenv/lib/python3.10/site-packages/vllm/connections.py:8: RuntimeWarning: Failed to read commit hash:
No module named 'vllm._version'
  from vllm.version import __version__ as VLLM_VERSION
/home/hkngae/anaconda3/envs/myenv/lib/python3.10/site-packages/vllm/connections.py:8: RuntimeWarning: Failed to read commit hash:
No module named 'vllm._version'
  from vllm.version import __version__ as VLLM_VERSION
/home/hkngae/anaconda3/envs/myenv/lib/python3.10/site-packages/vllm/connections.py:8: RuntimeWarning: Failed to read commit hash:
No module named 'vllm._version'
  from vllm.version import __version__ as VLLM_VERSION
Loading safetensors checkpoint shards:   0% Completed | 0/4 [00:00<?, ?it/s]
Loading safetensors checkpoint shards:  25% Completed | 1/4 [00:00<00:01,  2.02it/s]
Loading safetensors checkpoint shards:  50% Completed | 2/4 [00:00<00:00,  2.14it/s]
Loading safetensors checkpoint shards:  75% Completed | 3/4 [00:01<00:00,  3.23it/s]
Loading safetensors checkpoint shards: 100% Completed | 4/4 [00:01<00:00,  3.01it/s]
Loading safetensors checkpoint shards: 100% Completed | 4/4 [00:01<00:00,  2.79it/s]

INFO:     Started server process [1113274]
INFO:     Waiting for application startup.
INFO:     Application startup complete.
INFO:     Uvicorn running on socket ('0.0.0.0', 8000) (Press CTRL+C to quit)
Process SpawnProcess-1:
Traceback (most recent call last):
  File "/home/hkngae/anaconda3/envs/myenv/lib/python3.10/multiprocessing/process.py", line 314, in _bootstrap
    self.run()
  File "/home/hkngae/anaconda3/envs/myenv/lib/python3.10/multiprocessing/process.py", line 108, in run
    self._target(*self._args, **self._kwargs)
  File "/home/hkngae/anaconda3/envs/myenv/lib/python3.10/site-packages/vllm/engine/multiprocessing/engine.py", line 395, in run_mp_engine
    engine.start()
  File "/home/hkngae/anaconda3/envs/myenv/lib/python3.10/site-packages/vllm/engine/multiprocessing/engine.py", line 165, in start
    self.cleanup()
  File "/home/hkngae/anaconda3/envs/myenv/lib/python3.10/site-packages/vllm/engine/multiprocessing/engine.py", line 388, in signal_handler
    raise KeyboardInterrupt("MQLLMEngine terminated")
KeyboardInterrupt: MQLLMEngine terminated
INFO:     Shutting down
INFO:     Waiting for application shutdown.
INFO:     Application shutdown complete.
/home/hkngae/anaconda3/envs/myenv/lib/python3.10/multiprocessing/resource_tracker.py:224: UserWarning: resource_tracker: There appear to be 3 leaked semaphore objects to clean up at shutdown
  warnings.warn('resource_tracker: There appear to be %d '
/home/hkngae/anaconda3/envs/myenv/lib/python3.10/multiprocessing/resource_tracker.py:224: UserWarning: resource_tracker: There appear to be 1 leaked shared_memory objects to clean up at shutdown
  warnings.warn('resource_tracker: There appear to be %d '
/home/hkngae/anaconda3/envs/myenv/lib/python3.10/site-packages/vllm/connections.py:8: RuntimeWarning: Failed to read commit hash:
No module named 'vllm._version'
  from vllm.version import __version__ as VLLM_VERSION
/home/hkngae/anaconda3/envs/myenv/lib/python3.10/site-packages/vllm/connections.py:8: RuntimeWarning: Failed to read commit hash:
No module named 'vllm._version'
  from vllm.version import __version__ as VLLM_VERSION
/home/hkngae/anaconda3/envs/myenv/lib/python3.10/site-packages/vllm/connections.py:8: RuntimeWarning: Failed to read commit hash:
No module named 'vllm._version'
  from vllm.version import __version__ as VLLM_VERSION
/home/hkngae/anaconda3/envs/myenv/lib/python3.10/site-packages/vllm/connections.py:8: RuntimeWarning: Failed to read commit hash:
No module named 'vllm._version'
  from vllm.version import __version__ as VLLM_VERSION
/home/hkngae/anaconda3/envs/myenv/lib/python3.10/site-packages/vllm/connections.py:8: RuntimeWarning: Failed to read commit hash:
No module named 'vllm._version'
  from vllm.version import __version__ as VLLM_VERSION
Loading safetensors checkpoint shards:   0% Completed | 0/4 [00:00<?, ?it/s]
Loading safetensors checkpoint shards:  25% Completed | 1/4 [00:00<00:01,  2.22it/s]
Loading safetensors checkpoint shards:  50% Completed | 2/4 [00:00<00:00,  2.13it/s]
Loading safetensors checkpoint shards:  75% Completed | 3/4 [00:01<00:00,  3.18it/s]
Loading safetensors checkpoint shards: 100% Completed | 4/4 [00:01<00:00,  2.65it/s]
Loading safetensors checkpoint shards: 100% Completed | 4/4 [00:01<00:00,  2.60it/s]

INFO:     Started server process [1115390]
INFO:     Waiting for application startup.
INFO:     Application startup complete.
INFO:     Uvicorn running on socket ('0.0.0.0', 8000) (Press CTRL+C to quit)
Process SpawnProcess-1:
Traceback (most recent call last):
  File "/home/hkngae/anaconda3/envs/myenv/lib/python3.10/multiprocessing/process.py", line 314, in _bootstrap
    self.run()
  File "/home/hkngae/anaconda3/envs/myenv/lib/python3.10/multiprocessing/process.py", line 108, in run
    self._target(*self._args, **self._kwargs)
  File "/home/hkngae/anaconda3/envs/myenv/lib/python3.10/site-packages/vllm/engine/multiprocessing/engine.py", line 395, in run_mp_engine
    engine.start()
  File "/home/hkngae/anaconda3/envs/myenv/lib/python3.10/site-packages/vllm/engine/multiprocessing/engine.py", line 165, in start
    self.cleanup()
  File "/home/hkngae/anaconda3/envs/myenv/lib/python3.10/site-packages/vllm/engine/multiprocessing/engine.py", line 388, in signal_handler
    raise KeyboardInterrupt("MQLLMEngine terminated")
KeyboardInterrupt: MQLLMEngine terminated
INFO:     Shutting down
INFO:     Waiting for application shutdown.
INFO:     Application shutdown complete.
/home/hkngae/anaconda3/envs/myenv/lib/python3.10/multiprocessing/resource_tracker.py:224: UserWarning: resource_tracker: There appear to be 3 leaked semaphore objects to clean up at shutdown
  warnings.warn('resource_tracker: There appear to be %d '
/home/hkngae/anaconda3/envs/myenv/lib/python3.10/multiprocessing/resource_tracker.py:224: UserWarning: resource_tracker: There appear to be 1 leaked shared_memory objects to clean up at shutdown
  warnings.warn('resource_tracker: There appear to be %d '
/home/hkngae/anaconda3/envs/myenv/lib/python3.10/site-packages/vllm/connections.py:8: RuntimeWarning: Failed to read commit hash:
No module named 'vllm._version'
  from vllm.version import __version__ as VLLM_VERSION
/home/hkngae/anaconda3/envs/myenv/lib/python3.10/site-packages/vllm/connections.py:8: RuntimeWarning: Failed to read commit hash:
No module named 'vllm._version'
  from vllm.version import __version__ as VLLM_VERSION
/home/hkngae/anaconda3/envs/myenv/lib/python3.10/site-packages/vllm/connections.py:8: RuntimeWarning: Failed to read commit hash:
No module named 'vllm._version'
  from vllm.version import __version__ as VLLM_VERSION
/home/hkngae/anaconda3/envs/myenv/lib/python3.10/site-packages/vllm/connections.py:8: RuntimeWarning: Failed to read commit hash:
No module named 'vllm._version'
  from vllm.version import __version__ as VLLM_VERSION
/home/hkngae/anaconda3/envs/myenv/lib/python3.10/site-packages/vllm/connections.py:8: RuntimeWarning: Failed to read commit hash:
No module named 'vllm._version'
  from vllm.version import __version__ as VLLM_VERSION
Loading safetensors checkpoint shards:   0% Completed | 0/4 [00:00<?, ?it/s]
Loading safetensors checkpoint shards:  25% Completed | 1/4 [00:00<00:01,  2.34it/s]
Loading safetensors checkpoint shards:  50% Completed | 2/4 [00:00<00:00,  2.18it/s]
Loading safetensors checkpoint shards:  75% Completed | 3/4 [00:01<00:00,  3.26it/s]
Loading safetensors checkpoint shards: 100% Completed | 4/4 [00:01<00:00,  2.74it/s]
Loading safetensors checkpoint shards: 100% Completed | 4/4 [00:01<00:00,  2.69it/s]

INFO:     Started server process [1116599]
INFO:     Waiting for application startup.
INFO:     Application startup complete.
INFO:     Uvicorn running on socket ('0.0.0.0', 8000) (Press CTRL+C to quit)
Process SpawnProcess-1:
Traceback (most recent call last):
  File "/home/hkngae/anaconda3/envs/myenv/lib/python3.10/multiprocessing/process.py", line 314, in _bootstrap
    self.run()
  File "/home/hkngae/anaconda3/envs/myenv/lib/python3.10/multiprocessing/process.py", line 108, in run
    self._target(*self._args, **self._kwargs)
  File "/home/hkngae/anaconda3/envs/myenv/lib/python3.10/site-packages/vllm/engine/multiprocessing/engine.py", line 395, in run_mp_engine
    engine.start()
  File "/home/hkngae/anaconda3/envs/myenv/lib/python3.10/site-packages/vllm/engine/multiprocessing/engine.py", line 165, in start
    self.cleanup()
  File "/home/hkngae/anaconda3/envs/myenv/lib/python3.10/site-packages/vllm/engine/multiprocessing/engine.py", line 388, in signal_handler
    raise KeyboardInterrupt("MQLLMEngine terminated")
KeyboardInterrupt: MQLLMEngine terminated
INFO:     Shutting down
INFO:     Waiting for application shutdown.
INFO:     Application shutdown complete.
/home/hkngae/anaconda3/envs/myenv/lib/python3.10/multiprocessing/resource_tracker.py:224: UserWarning: resource_tracker: There appear to be 3 leaked semaphore objects to clean up at shutdown
  warnings.warn('resource_tracker: There appear to be %d '
/home/hkngae/anaconda3/envs/myenv/lib/python3.10/multiprocessing/resource_tracker.py:224: UserWarning: resource_tracker: There appear to be 1 leaked shared_memory objects to clean up at shutdown
  warnings.warn('resource_tracker: There appear to be %d '
/home/hkngae/anaconda3/envs/myenv/lib/python3.10/site-packages/vllm/connections.py:8: RuntimeWarning: Failed to read commit hash:
No module named 'vllm._version'
  from vllm.version import __version__ as VLLM_VERSION
Traceback (most recent call last):
  File "/home/hkngae/anaconda3/envs/myenv/bin/vllm", line 8, in <module>
    sys.exit(main())
  File "/home/hkngae/anaconda3/envs/myenv/lib/python3.10/site-packages/vllm/scripts.py", line 195, in main
    args.dispatch_function(args)
  File "/home/hkngae/anaconda3/envs/myenv/lib/python3.10/site-packages/vllm/scripts.py", line 41, in serve
    uvloop.run(run_server(args))
  File "/home/hkngae/anaconda3/envs/myenv/lib/python3.10/site-packages/uvloop/__init__.py", line 82, in run
    return loop.run_until_complete(wrapper())
  File "uvloop/loop.pyx", line 1517, in uvloop.loop.Loop.run_until_complete
  File "/home/hkngae/anaconda3/envs/myenv/lib/python3.10/site-packages/uvloop/__init__.py", line 61, in wrapper
    return await main
  File "/home/hkngae/anaconda3/envs/myenv/lib/python3.10/site-packages/vllm/entrypoints/openai/api_server.py", line 544, in run_server
    sock.bind(("", args.port))
OSError: [Errno 98] Address already in use
/home/hkngae/anaconda3/envs/myenv/lib/python3.10/site-packages/vllm/connections.py:8: RuntimeWarning: Failed to read commit hash:
No module named 'vllm._version'
  from vllm.version import __version__ as VLLM_VERSION
/home/hkngae/anaconda3/envs/myenv/lib/python3.10/site-packages/vllm/connections.py:8: RuntimeWarning: Failed to read commit hash:
No module named 'vllm._version'
  from vllm.version import __version__ as VLLM_VERSION
/home/hkngae/anaconda3/envs/myenv/lib/python3.10/site-packages/vllm/connections.py:8: RuntimeWarning: Failed to read commit hash:
No module named 'vllm._version'
  from vllm.version import __version__ as VLLM_VERSION
/home/hkngae/anaconda3/envs/myenv/lib/python3.10/site-packages/vllm/connections.py:8: RuntimeWarning: Failed to read commit hash:
No module named 'vllm._version'
  from vllm.version import __version__ as VLLM_VERSION
/home/hkngae/anaconda3/envs/myenv/lib/python3.10/site-packages/vllm/connections.py:8: RuntimeWarning: Failed to read commit hash:
No module named 'vllm._version'
  from vllm.version import __version__ as VLLM_VERSION
Loading safetensors checkpoint shards:   0% Completed | 0/4 [00:00<?, ?it/s]
Loading safetensors checkpoint shards:  25% Completed | 1/4 [00:00<00:01,  1.96it/s]
Loading safetensors checkpoint shards:  50% Completed | 2/4 [00:01<00:01,  1.96it/s]
Loading safetensors checkpoint shards:  75% Completed | 3/4 [00:01<00:00,  2.92it/s]
Loading safetensors checkpoint shards: 100% Completed | 4/4 [00:01<00:00,  2.61it/s]
Loading safetensors checkpoint shards: 100% Completed | 4/4 [00:01<00:00,  2.48it/s]

INFO:     Started server process [1119451]
INFO:     Waiting for application startup.
INFO:     Application startup complete.
INFO:     Uvicorn running on socket ('0.0.0.0', 8000) (Press CTRL+C to quit)
Process SpawnProcess-1:
Traceback (most recent call last):
  File "/home/hkngae/anaconda3/envs/myenv/lib/python3.10/multiprocessing/process.py", line 314, in _bootstrap
    self.run()
  File "/home/hkngae/anaconda3/envs/myenv/lib/python3.10/multiprocessing/process.py", line 108, in run
    self._target(*self._args, **self._kwargs)
  File "/home/hkngae/anaconda3/envs/myenv/lib/python3.10/site-packages/vllm/engine/multiprocessing/engine.py", line 395, in run_mp_engine
    engine.start()
  File "/home/hkngae/anaconda3/envs/myenv/lib/python3.10/site-packages/vllm/engine/multiprocessing/engine.py", line 165, in start
    self.cleanup()
  File "/home/hkngae/anaconda3/envs/myenv/lib/python3.10/site-packages/vllm/engine/multiprocessing/engine.py", line 388, in signal_handler
    raise KeyboardInterrupt("MQLLMEngine terminated")
KeyboardInterrupt: MQLLMEngine terminated
INFO:     Shutting down
INFO:     Waiting for application shutdown.
INFO:     Application shutdown complete.
/home/hkngae/anaconda3/envs/myenv/lib/python3.10/multiprocessing/resource_tracker.py:224: UserWarning: resource_tracker: There appear to be 3 leaked semaphore objects to clean up at shutdown
  warnings.warn('resource_tracker: There appear to be %d '
/home/hkngae/anaconda3/envs/myenv/lib/python3.10/multiprocessing/resource_tracker.py:224: UserWarning: resource_tracker: There appear to be 1 leaked shared_memory objects to clean up at shutdown
  warnings.warn('resource_tracker: There appear to be %d '
/home/hkngae/anaconda3/envs/myenv/lib/python3.10/site-packages/vllm/connections.py:8: RuntimeWarning: Failed to read commit hash:
No module named 'vllm._version'
  from vllm.version import __version__ as VLLM_VERSION
/home/hkngae/anaconda3/envs/myenv/lib/python3.10/site-packages/vllm/connections.py:8: RuntimeWarning: Failed to read commit hash:
No module named 'vllm._version'
  from vllm.version import __version__ as VLLM_VERSION
/home/hkngae/anaconda3/envs/myenv/lib/python3.10/site-packages/vllm/connections.py:8: RuntimeWarning: Failed to read commit hash:
No module named 'vllm._version'
  from vllm.version import __version__ as VLLM_VERSION
/home/hkngae/anaconda3/envs/myenv/lib/python3.10/site-packages/vllm/connections.py:8: RuntimeWarning: Failed to read commit hash:
No module named 'vllm._version'
  from vllm.version import __version__ as VLLM_VERSION
/home/hkngae/anaconda3/envs/myenv/lib/python3.10/site-packages/vllm/connections.py:8: RuntimeWarning: Failed to read commit hash:
No module named 'vllm._version'
  from vllm.version import __version__ as VLLM_VERSION
Loading safetensors checkpoint shards:   0% Completed | 0/4 [00:00<?, ?it/s]
Loading safetensors checkpoint shards:  25% Completed | 1/4 [00:00<00:01,  2.16it/s]
Loading safetensors checkpoint shards:  50% Completed | 2/4 [00:00<00:00,  2.19it/s]
Loading safetensors checkpoint shards:  75% Completed | 3/4 [00:01<00:00,  3.26it/s]
Loading safetensors checkpoint shards: 100% Completed | 4/4 [00:01<00:00,  2.86it/s]
Loading safetensors checkpoint shards: 100% Completed | 4/4 [00:01<00:00,  2.74it/s]

INFO:     Started server process [1123046]
INFO:     Waiting for application startup.
INFO:     Application startup complete.
INFO:     Uvicorn running on socket ('0.0.0.0', 8000) (Press CTRL+C to quit)
Process SpawnProcess-1:
Traceback (most recent call last):
  File "/home/hkngae/anaconda3/envs/myenv/lib/python3.10/multiprocessing/process.py", line 314, in _bootstrap
    self.run()
  File "/home/hkngae/anaconda3/envs/myenv/lib/python3.10/multiprocessing/process.py", line 108, in run
    self._target(*self._args, **self._kwargs)
  File "/home/hkngae/anaconda3/envs/myenv/lib/python3.10/site-packages/vllm/engine/multiprocessing/engine.py", line 395, in run_mp_engine
    engine.start()
  File "/home/hkngae/anaconda3/envs/myenv/lib/python3.10/site-packages/vllm/engine/multiprocessing/engine.py", line 165, in start
    self.cleanup()
  File "/home/hkngae/anaconda3/envs/myenv/lib/python3.10/site-packages/vllm/engine/multiprocessing/engine.py", line 388, in signal_handler
    raise KeyboardInterrupt("MQLLMEngine terminated")
KeyboardInterrupt: MQLLMEngine terminated
INFO:     Shutting down
INFO:     Waiting for application shutdown.
INFO:     Application shutdown complete.
/home/hkngae/anaconda3/envs/myenv/lib/python3.10/multiprocessing/resource_tracker.py:224: UserWarning: resource_tracker: There appear to be 3 leaked semaphore objects to clean up at shutdown
  warnings.warn('resource_tracker: There appear to be %d '
/home/hkngae/anaconda3/envs/myenv/lib/python3.10/multiprocessing/resource_tracker.py:224: UserWarning: resource_tracker: There appear to be 1 leaked shared_memory objects to clean up at shutdown
  warnings.warn('resource_tracker: There appear to be %d '
/home/hkngae/anaconda3/envs/myenv/lib/python3.10/site-packages/vllm/connections.py:8: RuntimeWarning: Failed to read commit hash:
No module named 'vllm._version'
  from vllm.version import __version__ as VLLM_VERSION
/home/hkngae/anaconda3/envs/myenv/lib/python3.10/site-packages/vllm/connections.py:8: RuntimeWarning: Failed to read commit hash:
No module named 'vllm._version'
  from vllm.version import __version__ as VLLM_VERSION
/home/hkngae/anaconda3/envs/myenv/lib/python3.10/site-packages/vllm/connections.py:8: RuntimeWarning: Failed to read commit hash:
No module named 'vllm._version'
  from vllm.version import __version__ as VLLM_VERSION
/home/hkngae/anaconda3/envs/myenv/lib/python3.10/site-packages/vllm/connections.py:8: RuntimeWarning: Failed to read commit hash:
No module named 'vllm._version'
  from vllm.version import __version__ as VLLM_VERSION
/home/hkngae/anaconda3/envs/myenv/lib/python3.10/site-packages/vllm/connections.py:8: RuntimeWarning: Failed to read commit hash:
No module named 'vllm._version'
  from vllm.version import __version__ as VLLM_VERSION
Loading safetensors checkpoint shards:   0% Completed | 0/4 [00:00<?, ?it/s]
Loading safetensors checkpoint shards:  25% Completed | 1/4 [00:00<00:01,  1.69it/s]
Loading safetensors checkpoint shards:  50% Completed | 2/4 [00:01<00:01,  1.69it/s]
Loading safetensors checkpoint shards:  75% Completed | 3/4 [00:01<00:00,  2.56it/s]
Loading safetensors checkpoint shards: 100% Completed | 4/4 [00:01<00:00,  2.19it/s]
Loading safetensors checkpoint shards: 100% Completed | 4/4 [00:01<00:00,  2.11it/s]

INFO:     Started server process [1124426]
INFO:     Waiting for application startup.
INFO:     Application startup complete.
INFO:     Uvicorn running on socket ('0.0.0.0', 8000) (Press CTRL+C to quit)
Process SpawnProcess-1:
Traceback (most recent call last):
  File "/home/hkngae/anaconda3/envs/myenv/lib/python3.10/multiprocessing/process.py", line 314, in _bootstrap
    self.run()
  File "/home/hkngae/anaconda3/envs/myenv/lib/python3.10/multiprocessing/process.py", line 108, in run
    self._target(*self._args, **self._kwargs)
  File "/home/hkngae/anaconda3/envs/myenv/lib/python3.10/site-packages/vllm/engine/multiprocessing/engine.py", line 395, in run_mp_engine
    engine.start()
  File "/home/hkngae/anaconda3/envs/myenv/lib/python3.10/site-packages/vllm/engine/multiprocessing/engine.py", line 165, in start
    self.cleanup()
  File "/home/hkngae/anaconda3/envs/myenv/lib/python3.10/site-packages/vllm/engine/multiprocessing/engine.py", line 388, in signal_handler
    raise KeyboardInterrupt("MQLLMEngine terminated")
KeyboardInterrupt: MQLLMEngine terminated
INFO:     Shutting down
INFO:     Waiting for application shutdown.
INFO:     Application shutdown complete.
/home/hkngae/anaconda3/envs/myenv/lib/python3.10/multiprocessing/resource_tracker.py:224: UserWarning: resource_tracker: There appear to be 3 leaked semaphore objects to clean up at shutdown
  warnings.warn('resource_tracker: There appear to be %d '
/home/hkngae/anaconda3/envs/myenv/lib/python3.10/multiprocessing/resource_tracker.py:224: UserWarning: resource_tracker: There appear to be 1 leaked shared_memory objects to clean up at shutdown
  warnings.warn('resource_tracker: There appear to be %d '
/home/hkngae/anaconda3/envs/myenv/lib/python3.10/site-packages/vllm/connections.py:8: RuntimeWarning: Failed to read commit hash:
No module named 'vllm._version'
  from vllm.version import __version__ as VLLM_VERSION
/home/hkngae/anaconda3/envs/myenv/lib/python3.10/site-packages/vllm/connections.py:8: RuntimeWarning: Failed to read commit hash:
No module named 'vllm._version'
  from vllm.version import __version__ as VLLM_VERSION
/home/hkngae/anaconda3/envs/myenv/lib/python3.10/site-packages/vllm/connections.py:8: RuntimeWarning: Failed to read commit hash:
No module named 'vllm._version'
  from vllm.version import __version__ as VLLM_VERSION
/home/hkngae/anaconda3/envs/myenv/lib/python3.10/site-packages/vllm/connections.py:8: RuntimeWarning: Failed to read commit hash:
No module named 'vllm._version'
  from vllm.version import __version__ as VLLM_VERSION
/home/hkngae/anaconda3/envs/myenv/lib/python3.10/site-packages/vllm/connections.py:8: RuntimeWarning: Failed to read commit hash:
No module named 'vllm._version'
  from vllm.version import __version__ as VLLM_VERSION
Loading safetensors checkpoint shards:   0% Completed | 0/4 [00:00<?, ?it/s]
Loading safetensors checkpoint shards:  25% Completed | 1/4 [00:00<00:01,  1.82it/s]
Loading safetensors checkpoint shards:  50% Completed | 2/4 [00:01<00:01,  1.84it/s]
Loading safetensors checkpoint shards:  75% Completed | 3/4 [00:01<00:00,  2.76it/s]
Loading safetensors checkpoint shards: 100% Completed | 4/4 [00:01<00:00,  2.58it/s]
Loading safetensors checkpoint shards: 100% Completed | 4/4 [00:01<00:00,  2.41it/s]

INFO:     Started server process [1125717]
INFO:     Waiting for application startup.
INFO:     Application startup complete.
INFO:     Uvicorn running on socket ('0.0.0.0', 8000) (Press CTRL+C to quit)
Process SpawnProcess-1:
Traceback (most recent call last):
  File "/home/hkngae/anaconda3/envs/myenv/lib/python3.10/multiprocessing/process.py", line 314, in _bootstrap
    self.run()
  File "/home/hkngae/anaconda3/envs/myenv/lib/python3.10/multiprocessing/process.py", line 108, in run
    self._target(*self._args, **self._kwargs)
  File "/home/hkngae/anaconda3/envs/myenv/lib/python3.10/site-packages/vllm/engine/multiprocessing/engine.py", line 395, in run_mp_engine
    engine.start()
  File "/home/hkngae/anaconda3/envs/myenv/lib/python3.10/site-packages/vllm/engine/multiprocessing/engine.py", line 165, in start
    self.cleanup()
  File "/home/hkngae/anaconda3/envs/myenv/lib/python3.10/site-packages/vllm/engine/multiprocessing/engine.py", line 388, in signal_handler
    raise KeyboardInterrupt("MQLLMEngine terminated")
KeyboardInterrupt: MQLLMEngine terminated
INFO:     Shutting down
INFO:     Waiting for application shutdown.
INFO:     Application shutdown complete.
/home/hkngae/anaconda3/envs/myenv/lib/python3.10/multiprocessing/resource_tracker.py:224: UserWarning: resource_tracker: There appear to be 3 leaked semaphore objects to clean up at shutdown
  warnings.warn('resource_tracker: There appear to be %d '
/home/hkngae/anaconda3/envs/myenv/lib/python3.10/multiprocessing/resource_tracker.py:224: UserWarning: resource_tracker: There appear to be 1 leaked shared_memory objects to clean up at shutdown
  warnings.warn('resource_tracker: There appear to be %d '
/home/hkngae/anaconda3/envs/myenv/lib/python3.10/site-packages/vllm/connections.py:8: RuntimeWarning: Failed to read commit hash:
No module named 'vllm._version'
  from vllm.version import __version__ as VLLM_VERSION
/home/hkngae/anaconda3/envs/myenv/lib/python3.10/site-packages/vllm/connections.py:8: RuntimeWarning: Failed to read commit hash:
No module named 'vllm._version'
  from vllm.version import __version__ as VLLM_VERSION
/home/hkngae/anaconda3/envs/myenv/lib/python3.10/site-packages/vllm/connections.py:8: RuntimeWarning: Failed to read commit hash:
No module named 'vllm._version'
  from vllm.version import __version__ as VLLM_VERSION
/home/hkngae/anaconda3/envs/myenv/lib/python3.10/site-packages/vllm/connections.py:8: RuntimeWarning: Failed to read commit hash:
No module named 'vllm._version'
  from vllm.version import __version__ as VLLM_VERSION
/home/hkngae/anaconda3/envs/myenv/lib/python3.10/site-packages/vllm/connections.py:8: RuntimeWarning: Failed to read commit hash:
No module named 'vllm._version'
  from vllm.version import __version__ as VLLM_VERSION
Loading safetensors checkpoint shards:   0% Completed | 0/4 [00:00<?, ?it/s]
Loading safetensors checkpoint shards:  25% Completed | 1/4 [00:00<00:01,  1.67it/s]
Loading safetensors checkpoint shards:  50% Completed | 2/4 [00:01<00:01,  1.61it/s]
Loading safetensors checkpoint shards:  75% Completed | 3/4 [00:01<00:00,  2.41it/s]
Loading safetensors checkpoint shards: 100% Completed | 4/4 [00:01<00:00,  2.12it/s]
Loading safetensors checkpoint shards: 100% Completed | 4/4 [00:01<00:00,  2.04it/s]

INFO:     Started server process [1126926]
INFO:     Waiting for application startup.
INFO:     Application startup complete.
INFO:     Uvicorn running on socket ('0.0.0.0', 8000) (Press CTRL+C to quit)
Process SpawnProcess-1:
Traceback (most recent call last):
  File "/home/hkngae/anaconda3/envs/myenv/lib/python3.10/multiprocessing/process.py", line 314, in _bootstrap
    self.run()
  File "/home/hkngae/anaconda3/envs/myenv/lib/python3.10/multiprocessing/process.py", line 108, in run
    self._target(*self._args, **self._kwargs)
  File "/home/hkngae/anaconda3/envs/myenv/lib/python3.10/site-packages/vllm/engine/multiprocessing/engine.py", line 395, in run_mp_engine
    engine.start()
  File "/home/hkngae/anaconda3/envs/myenv/lib/python3.10/site-packages/vllm/engine/multiprocessing/engine.py", line 165, in start
    self.cleanup()
  File "/home/hkngae/anaconda3/envs/myenv/lib/python3.10/site-packages/vllm/engine/multiprocessing/engine.py", line 388, in signal_handler
    raise KeyboardInterrupt("MQLLMEngine terminated")
KeyboardInterrupt: MQLLMEngine terminated
INFO:     Shutting down
INFO:     Waiting for application shutdown.
INFO:     Application shutdown complete.
/home/hkngae/anaconda3/envs/myenv/lib/python3.10/multiprocessing/resource_tracker.py:224: UserWarning: resource_tracker: There appear to be 3 leaked semaphore objects to clean up at shutdown
  warnings.warn('resource_tracker: There appear to be %d '
/home/hkngae/anaconda3/envs/myenv/lib/python3.10/multiprocessing/resource_tracker.py:224: UserWarning: resource_tracker: There appear to be 1 leaked shared_memory objects to clean up at shutdown
  warnings.warn('resource_tracker: There appear to be %d '
/home/hkngae/anaconda3/envs/myenv/lib/python3.10/site-packages/vllm/connections.py:8: RuntimeWarning: Failed to read commit hash:
No module named 'vllm._version'
  from vllm.version import __version__ as VLLM_VERSION
Traceback (most recent call last):
  File "/home/hkngae/anaconda3/envs/myenv/bin/vllm", line 8, in <module>
    sys.exit(main())
  File "/home/hkngae/anaconda3/envs/myenv/lib/python3.10/site-packages/vllm/scripts.py", line 195, in main
    args.dispatch_function(args)
  File "/home/hkngae/anaconda3/envs/myenv/lib/python3.10/site-packages/vllm/scripts.py", line 41, in serve
    uvloop.run(run_server(args))
  File "/home/hkngae/anaconda3/envs/myenv/lib/python3.10/site-packages/uvloop/__init__.py", line 82, in run
    return loop.run_until_complete(wrapper())
  File "uvloop/loop.pyx", line 1517, in uvloop.loop.Loop.run_until_complete
  File "/home/hkngae/anaconda3/envs/myenv/lib/python3.10/site-packages/uvloop/__init__.py", line 61, in wrapper
    return await main
  File "/home/hkngae/anaconda3/envs/myenv/lib/python3.10/site-packages/vllm/entrypoints/openai/api_server.py", line 544, in run_server
    sock.bind(("", args.port))
OSError: [Errno 98] Address already in use
/home/hkngae/anaconda3/envs/myenv/lib/python3.10/site-packages/vllm/connections.py:8: RuntimeWarning: Failed to read commit hash:
No module named 'vllm._version'
  from vllm.version import __version__ as VLLM_VERSION
/home/hkngae/anaconda3/envs/myenv/lib/python3.10/site-packages/vllm/connections.py:8: RuntimeWarning: Failed to read commit hash:
No module named 'vllm._version'
  from vllm.version import __version__ as VLLM_VERSION
/home/hkngae/anaconda3/envs/myenv/lib/python3.10/site-packages/vllm/connections.py:8: RuntimeWarning: Failed to read commit hash:
No module named 'vllm._version'
  from vllm.version import __version__ as VLLM_VERSION
/home/hkngae/anaconda3/envs/myenv/lib/python3.10/site-packages/vllm/connections.py:8: RuntimeWarning: Failed to read commit hash:
No module named 'vllm._version'
  from vllm.version import __version__ as VLLM_VERSION
/home/hkngae/anaconda3/envs/myenv/lib/python3.10/site-packages/vllm/connections.py:8: RuntimeWarning: Failed to read commit hash:
No module named 'vllm._version'
  from vllm.version import __version__ as VLLM_VERSION
Loading safetensors checkpoint shards:   0% Completed | 0/4 [00:00<?, ?it/s]
Loading safetensors checkpoint shards:  25% Completed | 1/4 [00:00<00:01,  1.89it/s]
Loading safetensors checkpoint shards:  50% Completed | 2/4 [00:01<00:01,  1.96it/s]
Loading safetensors checkpoint shards:  75% Completed | 3/4 [00:01<00:00,  2.99it/s]
Loading safetensors checkpoint shards: 100% Completed | 4/4 [00:01<00:00,  2.85it/s]
Loading safetensors checkpoint shards: 100% Completed | 4/4 [00:01<00:00,  2.62it/s]

INFO:     Started server process [1130187]
INFO:     Waiting for application startup.
INFO:     Application startup complete.
INFO:     Uvicorn running on socket ('0.0.0.0', 8000) (Press CTRL+C to quit)
Process SpawnProcess-1:
Traceback (most recent call last):
  File "/home/hkngae/anaconda3/envs/myenv/lib/python3.10/multiprocessing/process.py", line 314, in _bootstrap
    self.run()
  File "/home/hkngae/anaconda3/envs/myenv/lib/python3.10/multiprocessing/process.py", line 108, in run
    self._target(*self._args, **self._kwargs)
  File "/home/hkngae/anaconda3/envs/myenv/lib/python3.10/site-packages/vllm/engine/multiprocessing/engine.py", line 395, in run_mp_engine
    engine.start()
  File "/home/hkngae/anaconda3/envs/myenv/lib/python3.10/site-packages/vllm/engine/multiprocessing/engine.py", line 165, in start
    self.cleanup()
  File "/home/hkngae/anaconda3/envs/myenv/lib/python3.10/site-packages/vllm/engine/multiprocessing/engine.py", line 388, in signal_handler
    raise KeyboardInterrupt("MQLLMEngine terminated")
KeyboardInterrupt: MQLLMEngine terminated
INFO:     Shutting down
INFO:     Waiting for application shutdown.
INFO:     Application shutdown complete.
/home/hkngae/anaconda3/envs/myenv/lib/python3.10/multiprocessing/resource_tracker.py:224: UserWarning: resource_tracker: There appear to be 3 leaked semaphore objects to clean up at shutdown
  warnings.warn('resource_tracker: There appear to be %d '
/home/hkngae/anaconda3/envs/myenv/lib/python3.10/multiprocessing/resource_tracker.py:224: UserWarning: resource_tracker: There appear to be 1 leaked shared_memory objects to clean up at shutdown
  warnings.warn('resource_tracker: There appear to be %d '
/home/hkngae/anaconda3/envs/myenv/lib/python3.10/site-packages/vllm/connections.py:8: RuntimeWarning: Failed to read commit hash:
No module named 'vllm._version'
  from vllm.version import __version__ as VLLM_VERSION
Traceback (most recent call last):
  File "/home/hkngae/anaconda3/envs/myenv/bin/vllm", line 8, in <module>
    sys.exit(main())
  File "/home/hkngae/anaconda3/envs/myenv/lib/python3.10/site-packages/vllm/scripts.py", line 195, in main
    args.dispatch_function(args)
  File "/home/hkngae/anaconda3/envs/myenv/lib/python3.10/site-packages/vllm/scripts.py", line 41, in serve
    uvloop.run(run_server(args))
  File "/home/hkngae/anaconda3/envs/myenv/lib/python3.10/site-packages/uvloop/__init__.py", line 82, in run
    return loop.run_until_complete(wrapper())
  File "uvloop/loop.pyx", line 1517, in uvloop.loop.Loop.run_until_complete
  File "/home/hkngae/anaconda3/envs/myenv/lib/python3.10/site-packages/uvloop/__init__.py", line 61, in wrapper
    return await main
  File "/home/hkngae/anaconda3/envs/myenv/lib/python3.10/site-packages/vllm/entrypoints/openai/api_server.py", line 544, in run_server
    sock.bind(("", args.port))
OSError: [Errno 98] Address already in use
/home/hkngae/anaconda3/envs/myenv/lib/python3.10/site-packages/vllm/connections.py:8: RuntimeWarning: Failed to read commit hash:
No module named 'vllm._version'
  from vllm.version import __version__ as VLLM_VERSION
/home/hkngae/anaconda3/envs/myenv/lib/python3.10/site-packages/vllm/connections.py:8: RuntimeWarning: Failed to read commit hash:
No module named 'vllm._version'
  from vllm.version import __version__ as VLLM_VERSION
/home/hkngae/anaconda3/envs/myenv/lib/python3.10/site-packages/vllm/connections.py:8: RuntimeWarning: Failed to read commit hash:
No module named 'vllm._version'
  from vllm.version import __version__ as VLLM_VERSION
/home/hkngae/anaconda3/envs/myenv/lib/python3.10/site-packages/vllm/connections.py:8: RuntimeWarning: Failed to read commit hash:
No module named 'vllm._version'
  from vllm.version import __version__ as VLLM_VERSION
/home/hkngae/anaconda3/envs/myenv/lib/python3.10/site-packages/vllm/connections.py:8: RuntimeWarning: Failed to read commit hash:
No module named 'vllm._version'
  from vllm.version import __version__ as VLLM_VERSION
Loading safetensors checkpoint shards:   0% Completed | 0/4 [00:00<?, ?it/s]
Loading safetensors checkpoint shards:  25% Completed | 1/4 [00:00<00:01,  1.71it/s]
Loading safetensors checkpoint shards:  50% Completed | 2/4 [00:01<00:01,  1.74it/s]
Loading safetensors checkpoint shards:  75% Completed | 3/4 [00:01<00:00,  2.70it/s]
Loading safetensors checkpoint shards: 100% Completed | 4/4 [00:01<00:00,  2.68it/s]
Loading safetensors checkpoint shards: 100% Completed | 4/4 [00:01<00:00,  2.41it/s]

INFO:     Started server process [1133170]
INFO:     Waiting for application startup.
INFO:     Application startup complete.
INFO:     Uvicorn running on socket ('0.0.0.0', 8000) (Press CTRL+C to quit)
Process SpawnProcess-1:
Traceback (most recent call last):
  File "/home/hkngae/anaconda3/envs/myenv/lib/python3.10/multiprocessing/process.py", line 314, in _bootstrap
    self.run()
  File "/home/hkngae/anaconda3/envs/myenv/lib/python3.10/multiprocessing/process.py", line 108, in run
    self._target(*self._args, **self._kwargs)
  File "/home/hkngae/anaconda3/envs/myenv/lib/python3.10/site-packages/vllm/engine/multiprocessing/engine.py", line 395, in run_mp_engine
    engine.start()
  File "/home/hkngae/anaconda3/envs/myenv/lib/python3.10/site-packages/vllm/engine/multiprocessing/engine.py", line 165, in start
    self.cleanup()
  File "/home/hkngae/anaconda3/envs/myenv/lib/python3.10/site-packages/vllm/engine/multiprocessing/engine.py", line 388, in signal_handler
    raise KeyboardInterrupt("MQLLMEngine terminated")
KeyboardInterrupt: MQLLMEngine terminated
INFO:     Shutting down
INFO:     Waiting for application shutdown.
INFO:     Application shutdown complete.
/home/hkngae/anaconda3/envs/myenv/lib/python3.10/multiprocessing/resource_tracker.py:224: UserWarning: resource_tracker: There appear to be 3 leaked semaphore objects to clean up at shutdown
  warnings.warn('resource_tracker: There appear to be %d '
/home/hkngae/anaconda3/envs/myenv/lib/python3.10/multiprocessing/resource_tracker.py:224: UserWarning: resource_tracker: There appear to be 1 leaked shared_memory objects to clean up at shutdown
  warnings.warn('resource_tracker: There appear to be %d '
/home/hkngae/anaconda3/envs/myenv/lib/python3.10/site-packages/vllm/connections.py:8: RuntimeWarning: Failed to read commit hash:
No module named 'vllm._version'
  from vllm.version import __version__ as VLLM_VERSION
Traceback (most recent call last):
  File "/home/hkngae/anaconda3/envs/myenv/bin/vllm", line 8, in <module>
    sys.exit(main())
  File "/home/hkngae/anaconda3/envs/myenv/lib/python3.10/site-packages/vllm/scripts.py", line 195, in main
    args.dispatch_function(args)
  File "/home/hkngae/anaconda3/envs/myenv/lib/python3.10/site-packages/vllm/scripts.py", line 41, in serve
    uvloop.run(run_server(args))
  File "/home/hkngae/anaconda3/envs/myenv/lib/python3.10/site-packages/uvloop/__init__.py", line 82, in run
    return loop.run_until_complete(wrapper())
  File "uvloop/loop.pyx", line 1517, in uvloop.loop.Loop.run_until_complete
  File "/home/hkngae/anaconda3/envs/myenv/lib/python3.10/site-packages/uvloop/__init__.py", line 61, in wrapper
    return await main
  File "/home/hkngae/anaconda3/envs/myenv/lib/python3.10/site-packages/vllm/entrypoints/openai/api_server.py", line 544, in run_server
    sock.bind(("", args.port))
OSError: [Errno 98] Address already in use
/home/hkngae/anaconda3/envs/myenv/lib/python3.10/site-packages/vllm/connections.py:8: RuntimeWarning: Failed to read commit hash:
No module named 'vllm._version'
  from vllm.version import __version__ as VLLM_VERSION
/home/hkngae/anaconda3/envs/myenv/lib/python3.10/site-packages/vllm/connections.py:8: RuntimeWarning: Failed to read commit hash:
No module named 'vllm._version'
  from vllm.version import __version__ as VLLM_VERSION
/home/hkngae/anaconda3/envs/myenv/lib/python3.10/site-packages/vllm/connections.py:8: RuntimeWarning: Failed to read commit hash:
No module named 'vllm._version'
  from vllm.version import __version__ as VLLM_VERSION
/home/hkngae/anaconda3/envs/myenv/lib/python3.10/site-packages/vllm/connections.py:8: RuntimeWarning: Failed to read commit hash:
No module named 'vllm._version'
  from vllm.version import __version__ as VLLM_VERSION
/home/hkngae/anaconda3/envs/myenv/lib/python3.10/site-packages/vllm/connections.py:8: RuntimeWarning: Failed to read commit hash:
No module named 'vllm._version'
  from vllm.version import __version__ as VLLM_VERSION
Loading safetensors checkpoint shards:   0% Completed | 0/4 [00:00<?, ?it/s]
Loading safetensors checkpoint shards:  25% Completed | 1/4 [00:00<00:01,  2.33it/s]
Loading safetensors checkpoint shards:  50% Completed | 2/4 [00:00<00:00,  2.16it/s]
Loading safetensors checkpoint shards:  75% Completed | 3/4 [00:01<00:00,  3.23it/s]
Loading safetensors checkpoint shards: 100% Completed | 4/4 [00:01<00:00,  2.71it/s]
Loading safetensors checkpoint shards: 100% Completed | 4/4 [00:01<00:00,  2.66it/s]

INFO:     Started server process [1135906]
INFO:     Waiting for application startup.
INFO:     Application startup complete.
INFO:     Uvicorn running on socket ('0.0.0.0', 8000) (Press CTRL+C to quit)
Process SpawnProcess-1:
Traceback (most recent call last):
  File "/home/hkngae/anaconda3/envs/myenv/lib/python3.10/multiprocessing/process.py", line 314, in _bootstrap
    self.run()
  File "/home/hkngae/anaconda3/envs/myenv/lib/python3.10/multiprocessing/process.py", line 108, in run
    self._target(*self._args, **self._kwargs)
  File "/home/hkngae/anaconda3/envs/myenv/lib/python3.10/site-packages/vllm/engine/multiprocessing/engine.py", line 395, in run_mp_engine
    engine.start()
  File "/home/hkngae/anaconda3/envs/myenv/lib/python3.10/site-packages/vllm/engine/multiprocessing/engine.py", line 165, in start
    self.cleanup()
  File "/home/hkngae/anaconda3/envs/myenv/lib/python3.10/site-packages/vllm/engine/multiprocessing/engine.py", line 388, in signal_handler
    raise KeyboardInterrupt("MQLLMEngine terminated")
KeyboardInterrupt: MQLLMEngine terminated
INFO:     Shutting down
INFO:     Waiting for application shutdown.
INFO:     Application shutdown complete.
/home/hkngae/anaconda3/envs/myenv/lib/python3.10/multiprocessing/resource_tracker.py:224: UserWarning: resource_tracker: There appear to be 3 leaked semaphore objects to clean up at shutdown
  warnings.warn('resource_tracker: There appear to be %d '
/home/hkngae/anaconda3/envs/myenv/lib/python3.10/multiprocessing/resource_tracker.py:224: UserWarning: resource_tracker: There appear to be 1 leaked shared_memory objects to clean up at shutdown
  warnings.warn('resource_tracker: There appear to be %d '
/home/hkngae/anaconda3/envs/myenv/lib/python3.10/site-packages/vllm/connections.py:8: RuntimeWarning: Failed to read commit hash:
No module named 'vllm._version'
  from vllm.version import __version__ as VLLM_VERSION
/home/hkngae/anaconda3/envs/myenv/lib/python3.10/site-packages/vllm/connections.py:8: RuntimeWarning: Failed to read commit hash:
No module named 'vllm._version'
  from vllm.version import __version__ as VLLM_VERSION
/home/hkngae/anaconda3/envs/myenv/lib/python3.10/site-packages/vllm/connections.py:8: RuntimeWarning: Failed to read commit hash:
No module named 'vllm._version'
  from vllm.version import __version__ as VLLM_VERSION
/home/hkngae/anaconda3/envs/myenv/lib/python3.10/site-packages/vllm/connections.py:8: RuntimeWarning: Failed to read commit hash:
No module named 'vllm._version'
  from vllm.version import __version__ as VLLM_VERSION
/home/hkngae/anaconda3/envs/myenv/lib/python3.10/site-packages/vllm/connections.py:8: RuntimeWarning: Failed to read commit hash:
No module named 'vllm._version'
  from vllm.version import __version__ as VLLM_VERSION
Loading safetensors checkpoint shards:   0% Completed | 0/4 [00:00<?, ?it/s]
Loading safetensors checkpoint shards:  25% Completed | 1/4 [00:00<00:01,  1.74it/s]
Loading safetensors checkpoint shards:  50% Completed | 2/4 [00:01<00:01,  1.88it/s]
Loading safetensors checkpoint shards:  75% Completed | 3/4 [00:01<00:00,  2.89it/s]
Loading safetensors checkpoint shards: 100% Completed | 4/4 [00:01<00:00,  2.73it/s]
Loading safetensors checkpoint shards: 100% Completed | 4/4 [00:01<00:00,  2.50it/s]

INFO:     Started server process [1137851]
INFO:     Waiting for application startup.
INFO:     Application startup complete.
INFO:     Uvicorn running on socket ('0.0.0.0', 8000) (Press CTRL+C to quit)
Process SpawnProcess-1:
Traceback (most recent call last):
  File "/home/hkngae/anaconda3/envs/myenv/lib/python3.10/multiprocessing/process.py", line 314, in _bootstrap
    self.run()
  File "/home/hkngae/anaconda3/envs/myenv/lib/python3.10/multiprocessing/process.py", line 108, in run
    self._target(*self._args, **self._kwargs)
  File "/home/hkngae/anaconda3/envs/myenv/lib/python3.10/site-packages/vllm/engine/multiprocessing/engine.py", line 395, in run_mp_engine
    engine.start()
  File "/home/hkngae/anaconda3/envs/myenv/lib/python3.10/site-packages/vllm/engine/multiprocessing/engine.py", line 165, in start
    self.cleanup()
  File "/home/hkngae/anaconda3/envs/myenv/lib/python3.10/site-packages/vllm/engine/multiprocessing/engine.py", line 388, in signal_handler
    raise KeyboardInterrupt("MQLLMEngine terminated")
KeyboardInterrupt: MQLLMEngine terminated
INFO:     Shutting down
INFO:     Waiting for application shutdown.
INFO:     Application shutdown complete.
/home/hkngae/anaconda3/envs/myenv/lib/python3.10/multiprocessing/resource_tracker.py:224: UserWarning: resource_tracker: There appear to be 3 leaked semaphore objects to clean up at shutdown
  warnings.warn('resource_tracker: There appear to be %d '
/home/hkngae/anaconda3/envs/myenv/lib/python3.10/multiprocessing/resource_tracker.py:224: UserWarning: resource_tracker: There appear to be 1 leaked shared_memory objects to clean up at shutdown
  warnings.warn('resource_tracker: There appear to be %d '
/home/hkngae/anaconda3/envs/myenv/lib/python3.10/site-packages/vllm/connections.py:8: RuntimeWarning: Failed to read commit hash:
No module named 'vllm._version'
  from vllm.version import __version__ as VLLM_VERSION
/home/hkngae/anaconda3/envs/myenv/lib/python3.10/site-packages/vllm/connections.py:8: RuntimeWarning: Failed to read commit hash:
No module named 'vllm._version'
  from vllm.version import __version__ as VLLM_VERSION
/home/hkngae/anaconda3/envs/myenv/lib/python3.10/site-packages/vllm/connections.py:8: RuntimeWarning: Failed to read commit hash:
No module named 'vllm._version'
  from vllm.version import __version__ as VLLM_VERSION
/home/hkngae/anaconda3/envs/myenv/lib/python3.10/site-packages/vllm/connections.py:8: RuntimeWarning: Failed to read commit hash:
No module named 'vllm._version'
  from vllm.version import __version__ as VLLM_VERSION
/home/hkngae/anaconda3/envs/myenv/lib/python3.10/site-packages/vllm/connections.py:8: RuntimeWarning: Failed to read commit hash:
No module named 'vllm._version'
  from vllm.version import __version__ as VLLM_VERSION
Loading safetensors checkpoint shards:   0% Completed | 0/4 [00:00<?, ?it/s]
Loading safetensors checkpoint shards:  25% Completed | 1/4 [00:00<00:01,  1.70it/s]
Loading safetensors checkpoint shards:  50% Completed | 2/4 [00:01<00:01,  1.71it/s]
Loading safetensors checkpoint shards:  75% Completed | 3/4 [00:01<00:00,  2.59it/s]
Loading safetensors checkpoint shards: 100% Completed | 4/4 [00:01<00:00,  2.36it/s]
Loading safetensors checkpoint shards: 100% Completed | 4/4 [00:01<00:00,  2.22it/s]

INFO:     Started server process [1139915]
INFO:     Waiting for application startup.
INFO:     Application startup complete.
INFO:     Uvicorn running on socket ('0.0.0.0', 8000) (Press CTRL+C to quit)
Process SpawnProcess-1:
Traceback (most recent call last):
  File "/home/hkngae/anaconda3/envs/myenv/lib/python3.10/multiprocessing/process.py", line 314, in _bootstrap
    self.run()
  File "/home/hkngae/anaconda3/envs/myenv/lib/python3.10/multiprocessing/process.py", line 108, in run
    self._target(*self._args, **self._kwargs)
  File "/home/hkngae/anaconda3/envs/myenv/lib/python3.10/site-packages/vllm/engine/multiprocessing/engine.py", line 395, in run_mp_engine
    engine.start()
  File "/home/hkngae/anaconda3/envs/myenv/lib/python3.10/site-packages/vllm/engine/multiprocessing/engine.py", line 165, in start
    self.cleanup()
  File "/home/hkngae/anaconda3/envs/myenv/lib/python3.10/site-packages/vllm/engine/multiprocessing/engine.py", line 388, in signal_handler
    raise KeyboardInterrupt("MQLLMEngine terminated")
KeyboardInterrupt: MQLLMEngine terminated
INFO:     Shutting down
INFO:     Waiting for application shutdown.
INFO:     Application shutdown complete.
/home/hkngae/anaconda3/envs/myenv/lib/python3.10/multiprocessing/resource_tracker.py:224: UserWarning: resource_tracker: There appear to be 3 leaked semaphore objects to clean up at shutdown
  warnings.warn('resource_tracker: There appear to be %d '
/home/hkngae/anaconda3/envs/myenv/lib/python3.10/multiprocessing/resource_tracker.py:224: UserWarning: resource_tracker: There appear to be 1 leaked shared_memory objects to clean up at shutdown
  warnings.warn('resource_tracker: There appear to be %d '
/home/hkngae/anaconda3/envs/myenv/lib/python3.10/site-packages/vllm/connections.py:8: RuntimeWarning: Failed to read commit hash:
No module named 'vllm._version'
  from vllm.version import __version__ as VLLM_VERSION
/home/hkngae/anaconda3/envs/myenv/lib/python3.10/site-packages/vllm/connections.py:8: RuntimeWarning: Failed to read commit hash:
No module named 'vllm._version'
  from vllm.version import __version__ as VLLM_VERSION
/home/hkngae/anaconda3/envs/myenv/lib/python3.10/site-packages/vllm/connections.py:8: RuntimeWarning: Failed to read commit hash:
No module named 'vllm._version'
  from vllm.version import __version__ as VLLM_VERSION
/home/hkngae/anaconda3/envs/myenv/lib/python3.10/site-packages/vllm/connections.py:8: RuntimeWarning: Failed to read commit hash:
No module named 'vllm._version'
  from vllm.version import __version__ as VLLM_VERSION
/home/hkngae/anaconda3/envs/myenv/lib/python3.10/site-packages/vllm/connections.py:8: RuntimeWarning: Failed to read commit hash:
No module named 'vllm._version'
  from vllm.version import __version__ as VLLM_VERSION
Loading safetensors checkpoint shards:   0% Completed | 0/4 [00:00<?, ?it/s]
Loading safetensors checkpoint shards:  25% Completed | 1/4 [00:00<00:01,  1.98it/s]
Loading safetensors checkpoint shards:  50% Completed | 2/4 [00:01<00:01,  1.81it/s]
Loading safetensors checkpoint shards:  75% Completed | 3/4 [00:01<00:00,  2.70it/s]
Loading safetensors checkpoint shards: 100% Completed | 4/4 [00:01<00:00,  2.42it/s]
Loading safetensors checkpoint shards: 100% Completed | 4/4 [00:01<00:00,  2.32it/s]

INFO:     Started server process [1141622]
INFO:     Waiting for application startup.
INFO:     Application startup complete.
INFO:     Uvicorn running on socket ('0.0.0.0', 8000) (Press CTRL+C to quit)
Process SpawnProcess-1:
Traceback (most recent call last):
  File "/home/hkngae/anaconda3/envs/myenv/lib/python3.10/multiprocessing/process.py", line 314, in _bootstrap
    self.run()
  File "/home/hkngae/anaconda3/envs/myenv/lib/python3.10/multiprocessing/process.py", line 108, in run
    self._target(*self._args, **self._kwargs)
  File "/home/hkngae/anaconda3/envs/myenv/lib/python3.10/site-packages/vllm/engine/multiprocessing/engine.py", line 395, in run_mp_engine
    engine.start()
  File "/home/hkngae/anaconda3/envs/myenv/lib/python3.10/site-packages/vllm/engine/multiprocessing/engine.py", line 165, in start
    self.cleanup()
  File "/home/hkngae/anaconda3/envs/myenv/lib/python3.10/site-packages/vllm/engine/multiprocessing/engine.py", line 388, in signal_handler
    raise KeyboardInterrupt("MQLLMEngine terminated")
KeyboardInterrupt: MQLLMEngine terminated
INFO:     Shutting down
INFO:     Waiting for application shutdown.
INFO:     Application shutdown complete.
/home/hkngae/anaconda3/envs/myenv/lib/python3.10/multiprocessing/resource_tracker.py:224: UserWarning: resource_tracker: There appear to be 3 leaked semaphore objects to clean up at shutdown
  warnings.warn('resource_tracker: There appear to be %d '
/home/hkngae/anaconda3/envs/myenv/lib/python3.10/multiprocessing/resource_tracker.py:224: UserWarning: resource_tracker: There appear to be 1 leaked shared_memory objects to clean up at shutdown
  warnings.warn('resource_tracker: There appear to be %d '
/home/hkngae/anaconda3/envs/myenv/lib/python3.10/site-packages/vllm/connections.py:8: RuntimeWarning: Failed to read commit hash:
No module named 'vllm._version'
  from vllm.version import __version__ as VLLM_VERSION
/home/hkngae/anaconda3/envs/myenv/lib/python3.10/site-packages/vllm/connections.py:8: RuntimeWarning: Failed to read commit hash:
No module named 'vllm._version'
  from vllm.version import __version__ as VLLM_VERSION
/home/hkngae/anaconda3/envs/myenv/lib/python3.10/site-packages/vllm/connections.py:8: RuntimeWarning: Failed to read commit hash:
No module named 'vllm._version'
  from vllm.version import __version__ as VLLM_VERSION
/home/hkngae/anaconda3/envs/myenv/lib/python3.10/site-packages/vllm/connections.py:8: RuntimeWarning: Failed to read commit hash:
No module named 'vllm._version'
  from vllm.version import __version__ as VLLM_VERSION
/home/hkngae/anaconda3/envs/myenv/lib/python3.10/site-packages/vllm/connections.py:8: RuntimeWarning: Failed to read commit hash:
No module named 'vllm._version'
  from vllm.version import __version__ as VLLM_VERSION
Loading safetensors checkpoint shards:   0% Completed | 0/4 [00:00<?, ?it/s]
Loading safetensors checkpoint shards:  25% Completed | 1/4 [00:00<00:01,  1.82it/s]
Loading safetensors checkpoint shards:  50% Completed | 2/4 [00:01<00:01,  1.77it/s]
Loading safetensors checkpoint shards:  75% Completed | 3/4 [00:01<00:00,  2.67it/s]
Loading safetensors checkpoint shards: 100% Completed | 4/4 [00:01<00:00,  2.31it/s]
Loading safetensors checkpoint shards: 100% Completed | 4/4 [00:01<00:00,  2.23it/s]

INFO:     Started server process [1143297]
INFO:     Waiting for application startup.
INFO:     Application startup complete.
INFO:     Uvicorn running on socket ('0.0.0.0', 8000) (Press CTRL+C to quit)
Process SpawnProcess-1:
Traceback (most recent call last):
  File "/home/hkngae/anaconda3/envs/myenv/lib/python3.10/multiprocessing/process.py", line 314, in _bootstrap
    self.run()
  File "/home/hkngae/anaconda3/envs/myenv/lib/python3.10/multiprocessing/process.py", line 108, in run
    self._target(*self._args, **self._kwargs)
  File "/home/hkngae/anaconda3/envs/myenv/lib/python3.10/site-packages/vllm/engine/multiprocessing/engine.py", line 395, in run_mp_engine
    engine.start()
  File "/home/hkngae/anaconda3/envs/myenv/lib/python3.10/site-packages/vllm/engine/multiprocessing/engine.py", line 165, in start
    self.cleanup()
  File "/home/hkngae/anaconda3/envs/myenv/lib/python3.10/site-packages/vllm/engine/multiprocessing/engine.py", line 388, in signal_handler
    raise KeyboardInterrupt("MQLLMEngine terminated")
KeyboardInterrupt: MQLLMEngine terminated
INFO:     Shutting down
INFO:     Waiting for application shutdown.
INFO:     Application shutdown complete.
/home/hkngae/anaconda3/envs/myenv/lib/python3.10/multiprocessing/resource_tracker.py:224: UserWarning: resource_tracker: There appear to be 3 leaked semaphore objects to clean up at shutdown
  warnings.warn('resource_tracker: There appear to be %d '
/home/hkngae/anaconda3/envs/myenv/lib/python3.10/multiprocessing/resource_tracker.py:224: UserWarning: resource_tracker: There appear to be 1 leaked shared_memory objects to clean up at shutdown
  warnings.warn('resource_tracker: There appear to be %d '
/home/hkngae/anaconda3/envs/myenv/lib/python3.10/site-packages/vllm/connections.py:8: RuntimeWarning: Failed to read commit hash:
No module named 'vllm._version'
  from vllm.version import __version__ as VLLM_VERSION
/home/hkngae/anaconda3/envs/myenv/lib/python3.10/site-packages/vllm/connections.py:8: RuntimeWarning: Failed to read commit hash:
No module named 'vllm._version'
  from vllm.version import __version__ as VLLM_VERSION
/home/hkngae/anaconda3/envs/myenv/lib/python3.10/site-packages/vllm/connections.py:8: RuntimeWarning: Failed to read commit hash:
No module named 'vllm._version'
  from vllm.version import __version__ as VLLM_VERSION
/home/hkngae/anaconda3/envs/myenv/lib/python3.10/site-packages/vllm/connections.py:8: RuntimeWarning: Failed to read commit hash:
No module named 'vllm._version'
  from vllm.version import __version__ as VLLM_VERSION
/home/hkngae/anaconda3/envs/myenv/lib/python3.10/site-packages/vllm/connections.py:8: RuntimeWarning: Failed to read commit hash:
No module named 'vllm._version'
  from vllm.version import __version__ as VLLM_VERSION
Loading safetensors checkpoint shards:   0% Completed | 0/4 [00:00<?, ?it/s]
Loading safetensors checkpoint shards:  25% Completed | 1/4 [00:00<00:01,  2.07it/s]
Loading safetensors checkpoint shards:  50% Completed | 2/4 [00:00<00:00,  2.01it/s]
Loading safetensors checkpoint shards:  75% Completed | 3/4 [00:01<00:00,  2.97it/s]
Loading safetensors checkpoint shards: 100% Completed | 4/4 [00:01<00:00,  2.54it/s]
Loading safetensors checkpoint shards: 100% Completed | 4/4 [00:01<00:00,  2.47it/s]

INFO:     Started server process [1145331]
INFO:     Waiting for application startup.
INFO:     Application startup complete.
INFO:     Uvicorn running on socket ('0.0.0.0', 8000) (Press CTRL+C to quit)
Process SpawnProcess-1:
Traceback (most recent call last):
  File "/home/hkngae/anaconda3/envs/myenv/lib/python3.10/multiprocessing/process.py", line 314, in _bootstrap
    self.run()
  File "/home/hkngae/anaconda3/envs/myenv/lib/python3.10/multiprocessing/process.py", line 108, in run
    self._target(*self._args, **self._kwargs)
  File "/home/hkngae/anaconda3/envs/myenv/lib/python3.10/site-packages/vllm/engine/multiprocessing/engine.py", line 395, in run_mp_engine
    engine.start()
  File "/home/hkngae/anaconda3/envs/myenv/lib/python3.10/site-packages/vllm/engine/multiprocessing/engine.py", line 165, in start
    self.cleanup()
  File "/home/hkngae/anaconda3/envs/myenv/lib/python3.10/site-packages/vllm/engine/multiprocessing/engine.py", line 388, in signal_handler
    raise KeyboardInterrupt("MQLLMEngine terminated")
KeyboardInterrupt: MQLLMEngine terminated
INFO:     Shutting down
INFO:     Waiting for application shutdown.
INFO:     Application shutdown complete.
/home/hkngae/anaconda3/envs/myenv/lib/python3.10/multiprocessing/resource_tracker.py:224: UserWarning: resource_tracker: There appear to be 3 leaked semaphore objects to clean up at shutdown
  warnings.warn('resource_tracker: There appear to be %d '
/home/hkngae/anaconda3/envs/myenv/lib/python3.10/multiprocessing/resource_tracker.py:224: UserWarning: resource_tracker: There appear to be 1 leaked shared_memory objects to clean up at shutdown
  warnings.warn('resource_tracker: There appear to be %d '
/home/hkngae/anaconda3/envs/myenv/lib/python3.10/site-packages/vllm/connections.py:8: RuntimeWarning: Failed to read commit hash:
No module named 'vllm._version'
  from vllm.version import __version__ as VLLM_VERSION
/home/hkngae/anaconda3/envs/myenv/lib/python3.10/site-packages/vllm/connections.py:8: RuntimeWarning: Failed to read commit hash:
No module named 'vllm._version'
  from vllm.version import __version__ as VLLM_VERSION
/home/hkngae/anaconda3/envs/myenv/lib/python3.10/site-packages/vllm/connections.py:8: RuntimeWarning: Failed to read commit hash:
No module named 'vllm._version'
  from vllm.version import __version__ as VLLM_VERSION
/home/hkngae/anaconda3/envs/myenv/lib/python3.10/site-packages/vllm/connections.py:8: RuntimeWarning: Failed to read commit hash:
No module named 'vllm._version'
  from vllm.version import __version__ as VLLM_VERSION
/home/hkngae/anaconda3/envs/myenv/lib/python3.10/site-packages/vllm/connections.py:8: RuntimeWarning: Failed to read commit hash:
No module named 'vllm._version'
  from vllm.version import __version__ as VLLM_VERSION
Loading safetensors checkpoint shards:   0% Completed | 0/4 [00:00<?, ?it/s]
Loading safetensors checkpoint shards:  25% Completed | 1/4 [00:00<00:01,  1.69it/s]
Loading safetensors checkpoint shards:  50% Completed | 2/4 [00:01<00:01,  1.68it/s]
Loading safetensors checkpoint shards:  75% Completed | 3/4 [00:01<00:00,  2.53it/s]
Loading safetensors checkpoint shards: 100% Completed | 4/4 [00:01<00:00,  2.15it/s]
Loading safetensors checkpoint shards: 100% Completed | 4/4 [00:01<00:00,  2.09it/s]

INFO:     Started server process [1147999]
INFO:     Waiting for application startup.
INFO:     Application startup complete.
INFO:     Uvicorn running on socket ('0.0.0.0', 8000) (Press CTRL+C to quit)
INFO:     Shutting down
INFO:     Waiting for application shutdown.
INFO:     Application shutdown complete.
INFO:     Finished server process [1147999]
/home/hkngae/anaconda3/envs/myenv/lib/python3.10/multiprocessing/resource_tracker.py:224: UserWarning: resource_tracker: There appear to be 16 leaked semaphore objects to clean up at shutdown
  warnings.warn('resource_tracker: There appear to be %d '
/home/hkngae/anaconda3/envs/myenv/lib/python3.10/multiprocessing/resource_tracker.py:224: UserWarning: resource_tracker: There appear to be 1 leaked shared_memory objects to clean up at shutdown
  warnings.warn('resource_tracker: There appear to be %d '
