/home/hkngae/anaconda3/envs/myenv/lib/python3.10/site-packages/vllm/connections.py:8: RuntimeWarning: Failed to read commit hash:
No module named 'vllm._version'
  from vllm.version import __version__ as VLLM_VERSION
Traceback (most recent call last):
  File "/home/hkngae/anaconda3/envs/myenv/bin/vllm", line 8, in <module>
    sys.exit(main())
  File "/home/hkngae/anaconda3/envs/myenv/lib/python3.10/site-packages/vllm/scripts.py", line 195, in main
    args.dispatch_function(args)
  File "/home/hkngae/anaconda3/envs/myenv/lib/python3.10/site-packages/vllm/scripts.py", line 41, in serve
    uvloop.run(run_server(args))
  File "/home/hkngae/anaconda3/envs/myenv/lib/python3.10/site-packages/uvloop/__init__.py", line 82, in run
    return loop.run_until_complete(wrapper())
  File "uvloop/loop.pyx", line 1517, in uvloop.loop.Loop.run_until_complete
  File "/home/hkngae/anaconda3/envs/myenv/lib/python3.10/site-packages/uvloop/__init__.py", line 61, in wrapper
    return await main
  File "/home/hkngae/anaconda3/envs/myenv/lib/python3.10/site-packages/vllm/entrypoints/openai/api_server.py", line 544, in run_server
    sock.bind(("", args.port))
OSError: [Errno 98] Address already in use
/home/hkngae/anaconda3/envs/myenv/lib/python3.10/site-packages/vllm/connections.py:8: RuntimeWarning: Failed to read commit hash:
No module named 'vllm._version'
  from vllm.version import __version__ as VLLM_VERSION
/home/hkngae/anaconda3/envs/myenv/lib/python3.10/site-packages/vllm/connections.py:8: RuntimeWarning: Failed to read commit hash:
No module named 'vllm._version'
  from vllm.version import __version__ as VLLM_VERSION
/home/hkngae/anaconda3/envs/myenv/lib/python3.10/site-packages/vllm/connections.py:8: RuntimeWarning: Failed to read commit hash:
No module named 'vllm._version'
  from vllm.version import __version__ as VLLM_VERSION
/home/hkngae/anaconda3/envs/myenv/lib/python3.10/site-packages/vllm/connections.py:8: RuntimeWarning: Failed to read commit hash:
No module named 'vllm._version'
  from vllm.version import __version__ as VLLM_VERSION
/home/hkngae/anaconda3/envs/myenv/lib/python3.10/site-packages/vllm/connections.py:8: RuntimeWarning: Failed to read commit hash:
No module named 'vllm._version'
  from vllm.version import __version__ as VLLM_VERSION
Loading safetensors checkpoint shards:   0% Completed | 0/4 [00:00<?, ?it/s]
Loading safetensors checkpoint shards:  25% Completed | 1/4 [00:00<00:01,  1.82it/s]
Loading safetensors checkpoint shards:  50% Completed | 2/4 [00:01<00:01,  1.78it/s]
Loading safetensors checkpoint shards:  75% Completed | 3/4 [00:01<00:00,  2.68it/s]
Loading safetensors checkpoint shards: 100% Completed | 4/4 [00:01<00:00,  2.33it/s]
Loading safetensors checkpoint shards: 100% Completed | 4/4 [00:01<00:00,  2.24it/s]

INFO:     Started server process [1263260]
INFO:     Waiting for application startup.
INFO:     Application startup complete.
INFO:     Uvicorn running on socket ('0.0.0.0', 8000) (Press CTRL+C to quit)
Process SpawnProcess-1:
Traceback (most recent call last):
  File "/home/hkngae/anaconda3/envs/myenv/lib/python3.10/multiprocessing/process.py", line 314, in _bootstrap
    self.run()
  File "/home/hkngae/anaconda3/envs/myenv/lib/python3.10/multiprocessing/process.py", line 108, in run
    self._target(*self._args, **self._kwargs)
  File "/home/hkngae/anaconda3/envs/myenv/lib/python3.10/site-packages/vllm/engine/multiprocessing/engine.py", line 395, in run_mp_engine
    engine.start()
  File "/home/hkngae/anaconda3/envs/myenv/lib/python3.10/site-packages/vllm/engine/multiprocessing/engine.py", line 165, in start
    self.cleanup()
  File "/home/hkngae/anaconda3/envs/myenv/lib/python3.10/site-packages/vllm/engine/multiprocessing/engine.py", line 388, in signal_handler
    raise KeyboardInterrupt("MQLLMEngine terminated")
KeyboardInterrupt: MQLLMEngine terminated
INFO:     Shutting down
INFO:     Waiting for application shutdown.
INFO:     Application shutdown complete.
/home/hkngae/anaconda3/envs/myenv/lib/python3.10/multiprocessing/resource_tracker.py:224: UserWarning: resource_tracker: There appear to be 3 leaked semaphore objects to clean up at shutdown
  warnings.warn('resource_tracker: There appear to be %d '
/home/hkngae/anaconda3/envs/myenv/lib/python3.10/multiprocessing/resource_tracker.py:224: UserWarning: resource_tracker: There appear to be 1 leaked shared_memory objects to clean up at shutdown
  warnings.warn('resource_tracker: There appear to be %d '
/home/hkngae/anaconda3/envs/myenv/lib/python3.10/site-packages/vllm/connections.py:8: RuntimeWarning: Failed to read commit hash:
No module named 'vllm._version'
  from vllm.version import __version__ as VLLM_VERSION
/home/hkngae/anaconda3/envs/myenv/lib/python3.10/site-packages/vllm/connections.py:8: RuntimeWarning: Failed to read commit hash:
No module named 'vllm._version'
  from vllm.version import __version__ as VLLM_VERSION
/home/hkngae/anaconda3/envs/myenv/lib/python3.10/site-packages/vllm/connections.py:8: RuntimeWarning: Failed to read commit hash:
No module named 'vllm._version'
  from vllm.version import __version__ as VLLM_VERSION
/home/hkngae/anaconda3/envs/myenv/lib/python3.10/site-packages/vllm/connections.py:8: RuntimeWarning: Failed to read commit hash:
No module named 'vllm._version'
  from vllm.version import __version__ as VLLM_VERSION
/home/hkngae/anaconda3/envs/myenv/lib/python3.10/site-packages/vllm/connections.py:8: RuntimeWarning: Failed to read commit hash:
No module named 'vllm._version'
  from vllm.version import __version__ as VLLM_VERSION
Loading safetensors checkpoint shards:   0% Completed | 0/4 [00:00<?, ?it/s]
Loading safetensors checkpoint shards:  25% Completed | 1/4 [00:00<00:01,  1.76it/s]
Loading safetensors checkpoint shards:  50% Completed | 2/4 [00:01<00:01,  1.95it/s]
Loading safetensors checkpoint shards:  75% Completed | 3/4 [00:01<00:00,  3.01it/s]
Loading safetensors checkpoint shards: 100% Completed | 4/4 [00:01<00:00,  2.80it/s]
Loading safetensors checkpoint shards: 100% Completed | 4/4 [00:01<00:00,  2.57it/s]

INFO:     Started server process [1264983]
INFO:     Waiting for application startup.
INFO:     Application startup complete.
INFO:     Uvicorn running on socket ('0.0.0.0', 8000) (Press CTRL+C to quit)
Process SpawnProcess-1:
Traceback (most recent call last):
  File "/home/hkngae/anaconda3/envs/myenv/lib/python3.10/multiprocessing/process.py", line 314, in _bootstrap
    self.run()
  File "/home/hkngae/anaconda3/envs/myenv/lib/python3.10/multiprocessing/process.py", line 108, in run
    self._target(*self._args, **self._kwargs)
  File "/home/hkngae/anaconda3/envs/myenv/lib/python3.10/site-packages/vllm/engine/multiprocessing/engine.py", line 395, in run_mp_engine
    engine.start()
  File "/home/hkngae/anaconda3/envs/myenv/lib/python3.10/site-packages/vllm/engine/multiprocessing/engine.py", line 165, in start
    self.cleanup()
  File "/home/hkngae/anaconda3/envs/myenv/lib/python3.10/site-packages/vllm/engine/multiprocessing/engine.py", line 388, in signal_handler
    raise KeyboardInterrupt("MQLLMEngine terminated")
KeyboardInterrupt: MQLLMEngine terminated
INFO:     Shutting down
INFO:     Waiting for application shutdown.
INFO:     Application shutdown complete.
/home/hkngae/anaconda3/envs/myenv/lib/python3.10/multiprocessing/resource_tracker.py:224: UserWarning: resource_tracker: There appear to be 3 leaked semaphore objects to clean up at shutdown
  warnings.warn('resource_tracker: There appear to be %d '
/home/hkngae/anaconda3/envs/myenv/lib/python3.10/multiprocessing/resource_tracker.py:224: UserWarning: resource_tracker: There appear to be 1 leaked shared_memory objects to clean up at shutdown
  warnings.warn('resource_tracker: There appear to be %d '
/home/hkngae/anaconda3/envs/myenv/lib/python3.10/site-packages/vllm/connections.py:8: RuntimeWarning: Failed to read commit hash:
No module named 'vllm._version'
  from vllm.version import __version__ as VLLM_VERSION
/home/hkngae/anaconda3/envs/myenv/lib/python3.10/site-packages/vllm/connections.py:8: RuntimeWarning: Failed to read commit hash:
No module named 'vllm._version'
  from vllm.version import __version__ as VLLM_VERSION
/home/hkngae/anaconda3/envs/myenv/lib/python3.10/site-packages/vllm/connections.py:8: RuntimeWarning: Failed to read commit hash:
No module named 'vllm._version'
  from vllm.version import __version__ as VLLM_VERSION
/home/hkngae/anaconda3/envs/myenv/lib/python3.10/site-packages/vllm/connections.py:8: RuntimeWarning: Failed to read commit hash:
No module named 'vllm._version'
  from vllm.version import __version__ as VLLM_VERSION
/home/hkngae/anaconda3/envs/myenv/lib/python3.10/site-packages/vllm/connections.py:8: RuntimeWarning: Failed to read commit hash:
No module named 'vllm._version'
  from vllm.version import __version__ as VLLM_VERSION
Loading safetensors checkpoint shards:   0% Completed | 0/4 [00:00<?, ?it/s]
Loading safetensors checkpoint shards:  25% Completed | 1/4 [00:00<00:01,  1.97it/s]
Loading safetensors checkpoint shards:  50% Completed | 2/4 [00:00<00:00,  2.09it/s]
Loading safetensors checkpoint shards:  75% Completed | 3/4 [00:01<00:00,  3.17it/s]
Loading safetensors checkpoint shards: 100% Completed | 4/4 [00:01<00:00,  2.94it/s]
Loading safetensors checkpoint shards: 100% Completed | 4/4 [00:01<00:00,  2.73it/s]

INFO:     Started server process [1266753]
INFO:     Waiting for application startup.
INFO:     Application startup complete.
INFO:     Uvicorn running on socket ('0.0.0.0', 8000) (Press CTRL+C to quit)
Process SpawnProcess-1:
Traceback (most recent call last):
  File "/home/hkngae/anaconda3/envs/myenv/lib/python3.10/multiprocessing/process.py", line 314, in _bootstrap
    self.run()
  File "/home/hkngae/anaconda3/envs/myenv/lib/python3.10/multiprocessing/process.py", line 108, in run
    self._target(*self._args, **self._kwargs)
  File "/home/hkngae/anaconda3/envs/myenv/lib/python3.10/site-packages/vllm/engine/multiprocessing/engine.py", line 395, in run_mp_engine
    engine.start()
  File "/home/hkngae/anaconda3/envs/myenv/lib/python3.10/site-packages/vllm/engine/multiprocessing/engine.py", line 165, in start
    self.cleanup()
  File "/home/hkngae/anaconda3/envs/myenv/lib/python3.10/site-packages/vllm/engine/multiprocessing/engine.py", line 388, in signal_handler
    raise KeyboardInterrupt("MQLLMEngine terminated")
KeyboardInterrupt: MQLLMEngine terminated
INFO:     Shutting down
INFO:     Waiting for application shutdown.
INFO:     Application shutdown complete.
/home/hkngae/anaconda3/envs/myenv/lib/python3.10/multiprocessing/resource_tracker.py:224: UserWarning: resource_tracker: There appear to be 3 leaked semaphore objects to clean up at shutdown
  warnings.warn('resource_tracker: There appear to be %d '
/home/hkngae/anaconda3/envs/myenv/lib/python3.10/multiprocessing/resource_tracker.py:224: UserWarning: resource_tracker: There appear to be 1 leaked shared_memory objects to clean up at shutdown
  warnings.warn('resource_tracker: There appear to be %d '
/home/hkngae/anaconda3/envs/myenv/lib/python3.10/site-packages/vllm/connections.py:8: RuntimeWarning: Failed to read commit hash:
No module named 'vllm._version'
  from vllm.version import __version__ as VLLM_VERSION
/home/hkngae/anaconda3/envs/myenv/lib/python3.10/site-packages/vllm/connections.py:8: RuntimeWarning: Failed to read commit hash:
No module named 'vllm._version'
  from vllm.version import __version__ as VLLM_VERSION
/home/hkngae/anaconda3/envs/myenv/lib/python3.10/site-packages/vllm/connections.py:8: RuntimeWarning: Failed to read commit hash:
No module named 'vllm._version'
  from vllm.version import __version__ as VLLM_VERSION
/home/hkngae/anaconda3/envs/myenv/lib/python3.10/site-packages/vllm/connections.py:8: RuntimeWarning: Failed to read commit hash:
No module named 'vllm._version'
  from vllm.version import __version__ as VLLM_VERSION
/home/hkngae/anaconda3/envs/myenv/lib/python3.10/site-packages/vllm/connections.py:8: RuntimeWarning: Failed to read commit hash:
No module named 'vllm._version'
  from vllm.version import __version__ as VLLM_VERSION
Loading safetensors checkpoint shards:   0% Completed | 0/4 [00:00<?, ?it/s]
Loading safetensors checkpoint shards:  25% Completed | 1/4 [00:00<00:01,  2.12it/s]
Loading safetensors checkpoint shards:  50% Completed | 2/4 [00:00<00:00,  2.13it/s]
Loading safetensors checkpoint shards:  75% Completed | 3/4 [00:01<00:00,  3.15it/s]
Loading safetensors checkpoint shards: 100% Completed | 4/4 [00:01<00:00,  2.81it/s]
Loading safetensors checkpoint shards: 100% Completed | 4/4 [00:01<00:00,  2.68it/s]

INFO:     Started server process [1268849]
INFO:     Waiting for application startup.
INFO:     Application startup complete.
INFO:     Uvicorn running on socket ('0.0.0.0', 8000) (Press CTRL+C to quit)
Process SpawnProcess-1:
Traceback (most recent call last):
  File "/home/hkngae/anaconda3/envs/myenv/lib/python3.10/multiprocessing/process.py", line 314, in _bootstrap
    self.run()
  File "/home/hkngae/anaconda3/envs/myenv/lib/python3.10/multiprocessing/process.py", line 108, in run
    self._target(*self._args, **self._kwargs)
  File "/home/hkngae/anaconda3/envs/myenv/lib/python3.10/site-packages/vllm/engine/multiprocessing/engine.py", line 395, in run_mp_engine
    engine.start()
  File "/home/hkngae/anaconda3/envs/myenv/lib/python3.10/site-packages/vllm/engine/multiprocessing/engine.py", line 165, in start
    self.cleanup()
  File "/home/hkngae/anaconda3/envs/myenv/lib/python3.10/site-packages/vllm/engine/multiprocessing/engine.py", line 388, in signal_handler
    raise KeyboardInterrupt("MQLLMEngine terminated")
KeyboardInterrupt: MQLLMEngine terminated
INFO:     Shutting down
INFO:     Waiting for application shutdown.
INFO:     Application shutdown complete.
/home/hkngae/anaconda3/envs/myenv/lib/python3.10/multiprocessing/resource_tracker.py:224: UserWarning: resource_tracker: There appear to be 3 leaked semaphore objects to clean up at shutdown
  warnings.warn('resource_tracker: There appear to be %d '
/home/hkngae/anaconda3/envs/myenv/lib/python3.10/multiprocessing/resource_tracker.py:224: UserWarning: resource_tracker: There appear to be 1 leaked shared_memory objects to clean up at shutdown
  warnings.warn('resource_tracker: There appear to be %d '
/home/hkngae/anaconda3/envs/myenv/lib/python3.10/site-packages/vllm/connections.py:8: RuntimeWarning: Failed to read commit hash:
No module named 'vllm._version'
  from vllm.version import __version__ as VLLM_VERSION
/home/hkngae/anaconda3/envs/myenv/lib/python3.10/site-packages/vllm/connections.py:8: RuntimeWarning: Failed to read commit hash:
No module named 'vllm._version'
  from vllm.version import __version__ as VLLM_VERSION
/home/hkngae/anaconda3/envs/myenv/lib/python3.10/site-packages/vllm/connections.py:8: RuntimeWarning: Failed to read commit hash:
No module named 'vllm._version'
  from vllm.version import __version__ as VLLM_VERSION
/home/hkngae/anaconda3/envs/myenv/lib/python3.10/site-packages/vllm/connections.py:8: RuntimeWarning: Failed to read commit hash:
No module named 'vllm._version'
  from vllm.version import __version__ as VLLM_VERSION
/home/hkngae/anaconda3/envs/myenv/lib/python3.10/site-packages/vllm/connections.py:8: RuntimeWarning: Failed to read commit hash:
No module named 'vllm._version'
  from vllm.version import __version__ as VLLM_VERSION
Loading safetensors checkpoint shards:   0% Completed | 0/4 [00:00<?, ?it/s]
Loading safetensors checkpoint shards:  25% Completed | 1/4 [00:00<00:01,  1.75it/s]
Loading safetensors checkpoint shards:  50% Completed | 2/4 [00:01<00:01,  1.86it/s]
Loading safetensors checkpoint shards:  75% Completed | 3/4 [00:01<00:00,  2.86it/s]
Loading safetensors checkpoint shards: 100% Completed | 4/4 [00:01<00:00,  2.74it/s]
Loading safetensors checkpoint shards: 100% Completed | 4/4 [00:01<00:00,  2.50it/s]

INFO:     Started server process [1271031]
INFO:     Waiting for application startup.
INFO:     Application startup complete.
INFO:     Uvicorn running on socket ('0.0.0.0', 8000) (Press CTRL+C to quit)
Process SpawnProcess-1:
Traceback (most recent call last):
  File "/home/hkngae/anaconda3/envs/myenv/lib/python3.10/multiprocessing/process.py", line 314, in _bootstrap
    self.run()
  File "/home/hkngae/anaconda3/envs/myenv/lib/python3.10/multiprocessing/process.py", line 108, in run
    self._target(*self._args, **self._kwargs)
  File "/home/hkngae/anaconda3/envs/myenv/lib/python3.10/site-packages/vllm/engine/multiprocessing/engine.py", line 395, in run_mp_engine
    engine.start()
  File "/home/hkngae/anaconda3/envs/myenv/lib/python3.10/site-packages/vllm/engine/multiprocessing/engine.py", line 165, in start
    self.cleanup()
  File "/home/hkngae/anaconda3/envs/myenv/lib/python3.10/site-packages/vllm/engine/multiprocessing/engine.py", line 388, in signal_handler
    raise KeyboardInterrupt("MQLLMEngine terminated")
KeyboardInterrupt: MQLLMEngine terminated
INFO:     Shutting down
INFO:     Waiting for application shutdown.
INFO:     Application shutdown complete.
/home/hkngae/anaconda3/envs/myenv/lib/python3.10/multiprocessing/resource_tracker.py:224: UserWarning: resource_tracker: There appear to be 3 leaked semaphore objects to clean up at shutdown
  warnings.warn('resource_tracker: There appear to be %d '
/home/hkngae/anaconda3/envs/myenv/lib/python3.10/multiprocessing/resource_tracker.py:224: UserWarning: resource_tracker: There appear to be 1 leaked shared_memory objects to clean up at shutdown
  warnings.warn('resource_tracker: There appear to be %d '
/home/hkngae/anaconda3/envs/myenv/lib/python3.10/site-packages/vllm/connections.py:8: RuntimeWarning: Failed to read commit hash:
No module named 'vllm._version'
  from vllm.version import __version__ as VLLM_VERSION
/home/hkngae/anaconda3/envs/myenv/lib/python3.10/site-packages/vllm/connections.py:8: RuntimeWarning: Failed to read commit hash:
No module named 'vllm._version'
  from vllm.version import __version__ as VLLM_VERSION
/home/hkngae/anaconda3/envs/myenv/lib/python3.10/site-packages/vllm/connections.py:8: RuntimeWarning: Failed to read commit hash:
No module named 'vllm._version'
  from vllm.version import __version__ as VLLM_VERSION
/home/hkngae/anaconda3/envs/myenv/lib/python3.10/site-packages/vllm/connections.py:8: RuntimeWarning: Failed to read commit hash:
No module named 'vllm._version'
  from vllm.version import __version__ as VLLM_VERSION
/home/hkngae/anaconda3/envs/myenv/lib/python3.10/site-packages/vllm/connections.py:8: RuntimeWarning: Failed to read commit hash:
No module named 'vllm._version'
  from vllm.version import __version__ as VLLM_VERSION
Loading safetensors checkpoint shards:   0% Completed | 0/4 [00:00<?, ?it/s]
Loading safetensors checkpoint shards:  25% Completed | 1/4 [00:00<00:01,  1.85it/s]
Loading safetensors checkpoint shards:  50% Completed | 2/4 [00:01<00:01,  1.97it/s]
Loading safetensors checkpoint shards:  75% Completed | 3/4 [00:01<00:00,  3.01it/s]
Loading safetensors checkpoint shards: 100% Completed | 4/4 [00:01<00:00,  2.90it/s]
Loading safetensors checkpoint shards: 100% Completed | 4/4 [00:01<00:00,  2.64it/s]

INFO:     Started server process [1273659]
INFO:     Waiting for application startup.
INFO:     Application startup complete.
INFO:     Uvicorn running on socket ('0.0.0.0', 8000) (Press CTRL+C to quit)
Process SpawnProcess-1:
Traceback (most recent call last):
  File "/home/hkngae/anaconda3/envs/myenv/lib/python3.10/multiprocessing/process.py", line 314, in _bootstrap
    self.run()
  File "/home/hkngae/anaconda3/envs/myenv/lib/python3.10/multiprocessing/process.py", line 108, in run
    self._target(*self._args, **self._kwargs)
  File "/home/hkngae/anaconda3/envs/myenv/lib/python3.10/site-packages/vllm/engine/multiprocessing/engine.py", line 395, in run_mp_engine
    engine.start()
  File "/home/hkngae/anaconda3/envs/myenv/lib/python3.10/site-packages/vllm/engine/multiprocessing/engine.py", line 165, in start
    self.cleanup()
  File "/home/hkngae/anaconda3/envs/myenv/lib/python3.10/site-packages/vllm/engine/multiprocessing/engine.py", line 388, in signal_handler
    raise KeyboardInterrupt("MQLLMEngine terminated")
KeyboardInterrupt: MQLLMEngine terminated
INFO:     Shutting down
INFO:     Waiting for application shutdown.
INFO:     Application shutdown complete.
/home/hkngae/anaconda3/envs/myenv/lib/python3.10/multiprocessing/resource_tracker.py:224: UserWarning: resource_tracker: There appear to be 3 leaked semaphore objects to clean up at shutdown
  warnings.warn('resource_tracker: There appear to be %d '
/home/hkngae/anaconda3/envs/myenv/lib/python3.10/multiprocessing/resource_tracker.py:224: UserWarning: resource_tracker: There appear to be 1 leaked shared_memory objects to clean up at shutdown
  warnings.warn('resource_tracker: There appear to be %d '
/home/hkngae/anaconda3/envs/myenv/lib/python3.10/site-packages/vllm/connections.py:8: RuntimeWarning: Failed to read commit hash:
No module named 'vllm._version'
  from vllm.version import __version__ as VLLM_VERSION
/home/hkngae/anaconda3/envs/myenv/lib/python3.10/site-packages/vllm/connections.py:8: RuntimeWarning: Failed to read commit hash:
No module named 'vllm._version'
  from vllm.version import __version__ as VLLM_VERSION
/home/hkngae/anaconda3/envs/myenv/lib/python3.10/site-packages/vllm/connections.py:8: RuntimeWarning: Failed to read commit hash:
No module named 'vllm._version'
  from vllm.version import __version__ as VLLM_VERSION
/home/hkngae/anaconda3/envs/myenv/lib/python3.10/site-packages/vllm/connections.py:8: RuntimeWarning: Failed to read commit hash:
No module named 'vllm._version'
  from vllm.version import __version__ as VLLM_VERSION
/home/hkngae/anaconda3/envs/myenv/lib/python3.10/site-packages/vllm/connections.py:8: RuntimeWarning: Failed to read commit hash:
No module named 'vllm._version'
  from vllm.version import __version__ as VLLM_VERSION
Loading safetensors checkpoint shards:   0% Completed | 0/4 [00:00<?, ?it/s]
Loading safetensors checkpoint shards:  25% Completed | 1/4 [00:00<00:01,  1.79it/s]
Loading safetensors checkpoint shards:  50% Completed | 2/4 [00:01<00:01,  1.84it/s]
Loading safetensors checkpoint shards:  75% Completed | 3/4 [00:01<00:00,  2.82it/s]
Loading safetensors checkpoint shards: 100% Completed | 4/4 [00:01<00:00,  2.67it/s]
Loading safetensors checkpoint shards: 100% Completed | 4/4 [00:01<00:00,  2.46it/s]

INFO:     Started server process [1277469]
INFO:     Waiting for application startup.
INFO:     Application startup complete.
INFO:     Uvicorn running on socket ('0.0.0.0', 8000) (Press CTRL+C to quit)
Process SpawnProcess-1:
Traceback (most recent call last):
  File "/home/hkngae/anaconda3/envs/myenv/lib/python3.10/multiprocessing/process.py", line 314, in _bootstrap
    self.run()
  File "/home/hkngae/anaconda3/envs/myenv/lib/python3.10/multiprocessing/process.py", line 108, in run
    self._target(*self._args, **self._kwargs)
  File "/home/hkngae/anaconda3/envs/myenv/lib/python3.10/site-packages/vllm/engine/multiprocessing/engine.py", line 395, in run_mp_engine
    engine.start()
  File "/home/hkngae/anaconda3/envs/myenv/lib/python3.10/site-packages/vllm/engine/multiprocessing/engine.py", line 165, in start
    self.cleanup()
  File "/home/hkngae/anaconda3/envs/myenv/lib/python3.10/site-packages/vllm/engine/multiprocessing/engine.py", line 388, in signal_handler
    raise KeyboardInterrupt("MQLLMEngine terminated")
KeyboardInterrupt: MQLLMEngine terminated
INFO:     Shutting down
INFO:     Waiting for application shutdown.
INFO:     Application shutdown complete.
/home/hkngae/anaconda3/envs/myenv/lib/python3.10/multiprocessing/resource_tracker.py:224: UserWarning: resource_tracker: There appear to be 3 leaked semaphore objects to clean up at shutdown
  warnings.warn('resource_tracker: There appear to be %d '
/home/hkngae/anaconda3/envs/myenv/lib/python3.10/multiprocessing/resource_tracker.py:224: UserWarning: resource_tracker: There appear to be 1 leaked shared_memory objects to clean up at shutdown
  warnings.warn('resource_tracker: There appear to be %d '
